Workbook
Name TIPO_LANCAMENTO: 'CONFIGURAÇÕES'!$F$36:$F$37
Name SITUACAO: 'CONFIGURAÇÕES'!$G$36:$G$41
Name FORMA_PAGAMENTO: 'CONFIGURAÇÕES'!$H$36:$H$44
Name TIPO_CONTA: 'CONFIGURAÇÕES'!$I$36:$I$45
Name STATUS_CADASTRO: 'CONFIGURAÇÕES'!$J$36:$J$38
Name PERIODICIDADE: 'CONFIGURAÇÕES'!$K$36:$K$40
Name SISTEMA_AMORTIZACAO: 'CONFIGURAÇÕES'!$L$36:$L$37
Name TIPO_FLUXO: 'CONFIGURAÇÕES'!$M$36:$M$38
Name BANDEIRA: 'CONFIGURAÇÕES'!$N$36:$N$41
Name STATUS_CONCILIACAO: 'CONFIGURAÇÕES'!$O$36:$O$38
Name SIM_NAO: 'CONFIGURAÇÕES'!$P$36:$P$37
Name REGIME: 'CONFIGURAÇÕES'!$Q$36:$Q$39
Name UF: 'CONFIGURAÇÕES'!$R$36:$R$62
Name MESES: 'CONFIGURAÇÕES'!$S$36:$S$47
Name TIPO_OPERACAO: 'CONFIGURAÇÕES'!$T$36:$T$38
Name SUBGRUPOS: 'CONFIGURAÇÕES'!$U$36:$U$48
Name STATUS_CONTRATO: 'CONFIGURAÇÕES'!$V$36:$V$39
Name LINHAS_DRE: 'CONFIGURAÇÕES'!$W$36:$W$47
Name CLIENTES_NOMES: 'CADASTRO DE CLIENTES'!$B$6:$B$65
Name CLIENTES_FANTASIA: 'CADASTRO DE CLIENTES'!$C$6:$C$65
Name FORNECEDORES_NOMES: 'CADASTRO DE FORNECEDORES'!$B$6:$B$65
Name FORNECEDORES_FANTASIA: 'CADASTRO DE FORNECEDORES'!$C$6:$C$65
Name CATEGORIAS_PLANO: 'PLANO DE CONTAS'!$C$6:$C$85
Name SUBGRUPOS_PLANO: 'PLANO DE CONTAS'!$C$6:$C$85
Name SUBCATEGORIAS_PLANO: 'PLANO DE CONTAS'!$D$6:$D$85
Name LINHAS_DRE_PLANO: 'PLANO DE CONTAS'!$H$6:$H$85
Name GRUPOS_PLANO: 'PLANO DE CONTAS'!$B$6:$B$85
Name TIPOS_FLUXO_PLANO: 'PLANO DE CONTAS'!$G$6:$G$85
Name CENTROS_CUSTO: 'CENTRO DE CUSTOS'!$B$6:$B$25
Name CONTAS_BANCARIAS: 'CONTAS BANCÁRIAS'!$B$6:$B$13
Name CARTOES: 'CARTÕES'!$B$6:$B$15
Name CARTAO_LISTA: 'CARTÕES'!$B$6:$B$15
Name LANC_ID: 'LANÇAMENTOS'!$A$6:$A$2005
Name PE_MC_UNIT: 'PONTO DE EQUILÍBRIO'!$B$17
Name PE_RS: 'PONTO DE EQUILÍBRIO'!$B$18
Name PE_QTD: 'PONTO DE EQUILÍBRIO'!$B$19
Name MARGEM_SEGURANCA: 'PONTO DE EQUILÍBRIO'!$B$21
Name RECORRENTES_MES: 'DESPESAS RECORRENTES'!$C$137:$N$137

Sheet PAINEL DE CONTROLE
B2: =IF('CONFIGURAÇÕES'!$B$6="","GESTÃO FINANCEIRA EMPRESARIAL",'CONFIGURAÇÕES'!$B$6)
B4: Sistema completo de gestão financeira: lançamentos, contas a pagar e a receber, fluxo de caixa, DRE gerencial, orçamento, empréstimos, indicadores e dashboard executivo.
B5: ="Hoje: "&TEXT(TODAY(),"DD/MM/YYYY")&" | Ano de análise: "&'CONFIGURAÇÕES'!$B$18&" | Mês de análise: "&IF('CONFIGURAÇÕES'!$B$19=0,"ano completo",TEXT(DATE('CONFIGURAÇÕES'!$B$18,'CONFIGURAÇÕES'!$B$19,1),"MM/YYYY"))&" | Arquivo: Excel (xlsx) e Google Sheets"
B7: SITUAÇÃO ATUAL
B8: Saldo de caixa disponível | D8: Faturamento do mês de análise
B9: =SUM('CONTAS BANCÁRIAS'!$G$6:$G$13)+SUMIFS('LANÇAMENTOS'!$V$6:$V$2005,'LANÇAMENTOS'!$E$6:$E$2005,"Entrada",'LANÇAMENTOS'!$D$6:$D$2005,"<="&TODAY())-SUMIFS('LANÇAMENTOS'!$V$6:$V$2005,'LANÇAMENTOS'!$E$6:$E$2005,"Saída",'LANÇAMENTOS'!$D$6:$D$2005,"<="&TODAY()) | D9: =SUMIFS('LANÇAMENTOS'!$AE$6:$AE$2005,'LANÇAMENTOS'!$AF$6:$AF$2005,"Faturamento Bruto",'LANÇAMENTOS'!$AA$6:$AA$2005,'CONFIGURAÇÕES'!$B$18,'LANÇAMENTOS'!$Z$6:$Z$2005,'CONFIGURAÇÕES'!$B$19)
B11: A receber em aberto | D11: A pagar em aberto
B12: =SUMIFS('LANÇAMENTOS'!$W$6:$W$2005,'LANÇAMENTOS'!$E$6:$E$2005,"Entrada") | D12: =SUMIFS('LANÇAMENTOS'!$W$6:$W$2005,'LANÇAMENTOS'!$E$6:$E$2005,"Saída")
B15: MENU — CLIQUE NAS TELAS ABAIXO PARA NAVEGAR
B16: 📊 DASHBOARD | D16: ✍️ LANÇAR ENTRADA
B17: Visão executiva: cartões, gráficos e alertas. | D17: Registre uma receita na aba LANÇAMENTOS.
B19: ✍️ LANÇAR SAÍDA | D19: 📄 CONTAS A PAGAR
B20: Registre uma despesa na aba LANÇAMENTOS. | D20: Títulos a pagar, aging e prioridades.
B22: 📥 CONTAS A RECEBER | D22: 💧 FLUXO DE CAIXA
B23: Carteira, recebimentos e prazos. | D23: Entradas, saídas, saldos e projeções.
B25: 📈 DRE GERENCIAL | D25: 👥 CLIENTES
B26: Resultado por competência e margens. | D26: Cadastro e indicadores por cliente.
B28: 🏭 FORNECEDORES | D28: 🏦 BANCOS E CARTÕES
B29: Cadastro e indicadores por fornecedor. | D29: Contas, saldos, limites e faturas.
B31: 🧾 RELATÓRIOS | D31: ⚙️ CONFIGURAÇÕES
B32: Relatórios resumidos para imprimir. | D32: Empresa, metas, parâmetros e listas.
B34: Dica: os lançamentos são a base de tudo — cadastre cliente/fornecedor e categoria antes de lançar. Todas as demais abas se atualizam sozinhas.
B36: COMECE POR AQUI — ROTEIRO DE 6 PASSOS
B37: 1. Configurações | C37: Informe os dados da empresa, as metas e o ano/mês de análise. Confira as listas auxiliares que alimentam os menus suspensos.
B38: 2. Cadastros | C38: Cadastre clientes, fornecedores, plano de contas, centros de custo, contas bancárias e cartões.
B39: 3. Lançamentos | C39: Registre todas as entradas e saídas. Use os menus suspensos e preencha as células amarelas; as colunas cinzas são calculadas.
B40: 4. Conferência | C40: Verifique contas a pagar e a receber, a conciliação bancária e a coluna de validação dos lançamentos.
B41: 5. Análise | C41: Acompanhe o dashboard, o DRE, o fluxo de caixa, o orçamento e os indicadores.
B42: 6. Planejamento | C42: Use ponto de equilíbrio, projeção de caixa, simulador de cenários e despesas recorrentes para decidir.
B44: ⚠ Esta planilha acompanha DADOS DE EXEMPLO (empresa fictícia) para você testar todos os recursos. Antes de usar de verdade, apague os dados de exemplo — veja o passo a passo na aba INSTRUÇÕES.
B45: Versão 1.0 — 25 abas — Compatível com Microsoft Excel 2016+ e Google Sheets.

Sheet DASHBOARD
B1: =IF('CONFIGURAÇÕES'!$B$6="","DASHBOARD EXECUTIVO",'CONFIGURAÇÕES'!$B$6&" — DASHBOARD EXECUTIVO")
B3: ="Atualizado em "&TEXT(TODAY(),"DD/MM/YYYY")&" | Ano de análise: "&'CONFIGURAÇÕES'!$B$18&" | Mês de análise: "&IF('CONFIGURAÇÕES'!$B$19=0,"ano completo",TEXT(DATE('CONFIGURAÇÕES'!$B$18,'CONFIGURAÇÕES'!$B$19,1),"MM/AAAA"))&" | Todos os valores são calculados automaticamente a partir da aba LANÇAMENTOS."
B5: 🎛️ FILTROS — altere para analisar o período, o centro de custo, a categoria, a conta ou o tipo de operação
B6: Ano | D6: Mês (0 = ano todo) | F6: Centro de custo | H6: Categoria (subcategoria) | J6: Conta / cartão | L6: Tipo de operação | N6: ="Lançamentos no filtro: "&TEXT($B$146,"#,##0")
B7: ='CONFIGURAÇÕES'!$B$18 | D7: ='CONFIGURAÇÕES'!$B$19 | F7: Todos | H7: Todos | J7: Todos | L7: Todos
B10: 📌 INDICADORES PRINCIPAIS DO PERÍODO FILTRADO
B11: Faturamento do período | D11: Lucro líquido do período | F11: Margem líquida | H11: Saldo de caixa hoje | J11: A receber em aberto | L11: A pagar em aberto | N11: Vencido a receber | P11: Vencido a pagar
B12: =$B$131 | D12: =$B$140 | F12: =$B$141 | H12: =SUM('CONTAS BANCÁRIAS'!$G$6:$G$13)+SUMIFS('LANÇAMENTOS'!$V$6:$V$2005,'LANÇAMENTOS'!$E$6:$E$2005,"Entrada",'LANÇAMENTOS'!$D$6:$D$2005,"<="&TODAY())-SUMIFS('LANÇAMENTOS'!$V$6:$V$2005,'LANÇAMENTOS'!$E$6:$E$2005,"Saída",'LANÇAMENTOS'!$D$6:$D$2005,"<="&TODAY()) | J12: =$B$147 | L12: =$B$148 | N12: =$B$149 | P12: =$B$150
B13: Entradas de caixa do período | D13: Saídas de caixa do período | F13: Geração de caixa do período | H13: Orçado no período | J13: Realizado no período | L13: Consumo do orçamento | N13: Margem de contribuição | P13: Lançamentos no filtro
B14: =$B$142 | D14: =$B$143 | F14: =$B$144 | H14: =$B$151 | J14: =$B$152 | L14: =$B$153 | N14: =$B$139 | P14: =$B$146
B16: 🔔 ATENÇÃO DO GESTOR — SITUAÇÕES QUE EXIGEM DECISÃO
B17: ='INDICADORES'!$A$7 | I17: ='INDICADORES'!$B$7 | L17: ='INDICADORES'!$C$7 | N17: ='INDICADORES'!$A$16 | Q17: ='INDICADORES'!$B$16
B18: ='INDICADORES'!$A$8 | I18: ='INDICADORES'!$B$8 | L18: ='INDICADORES'!$C$8 | N18: ='INDICADORES'!$A$17 | Q18: ='INDICADORES'!$B$17
B19: ='INDICADORES'!$A$9 | I19: ='INDICADORES'!$B$9 | L19: ='INDICADORES'!$C$9 | N19: ='INDICADORES'!$A$18 | Q19: ='INDICADORES'!$B$18
B20: ='INDICADORES'!$A$10 | I20: ='INDICADORES'!$B$10 | L20: ='INDICADORES'!$C$10 | N20: ='INDICADORES'!$A$19 | Q20: ='INDICADORES'!$B$19
B21: ='INDICADORES'!$A$11 | I21: ='INDICADORES'!$B$11 | L21: ='INDICADORES'!$C$11 | N21: ='INDICADORES'!$A$20 | Q21: ='INDICADORES'!$B$20
B22: ='INDICADORES'!$A$12 | I22: ='INDICADORES'!$B$12 | L22: ='INDICADORES'!$C$12 | N22: ='INDICADORES'!$A$21 | Q22: ='INDICADORES'!$B$21
B23: ='INDICADORES'!$A$13 | I23: ='INDICADORES'!$B$13 | L23: ='INDICADORES'!$C$13 | N23: ='INDICADORES'!$A$22 | Q23: ='INDICADORES'!$B$22
B24: ='INDICADORES'!$A$14 | I24: ='INDICADORES'!$B$14 | L24: ='INDICADORES'!$C$14 | N24: ='INDICADORES'!$A$23 | Q24: ='INDICADORES'!$B$23
B25: ='INDICADORES'!$A$15 | I25: ='INDICADORES'!$B$15 | L25: ='INDICADORES'!$C$15 | N25: ='INDICADORES'!$A$24 | Q25: ='INDICADORES'!$B$24
B26: Painel completo com as 18 verificações, valores de referência e ações recomendadas na aba INDICADORES (bloco ATENÇÃO DO GESTOR).
B27: 📋 RESUMO EXECUTIVO DO PERÍODO FILTRADO
B28: Faturamento do período | D28: =$B$131 | F28: Impostos e devoluções | H28: =$B$132 | J28: Receita líquida | L28: =$B$136 | N28: Custos variáveis | P28: =$B$133
B29: Despesas fixas | D29: =$B$134 | F29: Despesas financeiras | H29: =$B$135 | J29: Impostos sobre o lucro | L29: =$B$138 | N29: Lucro líquido | P29: =$B$140
B31: 📈 GRÁFICOS GERENCIAIS — atualizam automaticamente com os lançamentos
B128: ÁREA DE APOIO — CÁLCULOS DO DASHBOARD (não editar; os cartões acima referenciam estas células)
B129: Valor calculado | C129: Linha calculada (base dos cartões acima)
B131: =SUMIFS('LANÇAMENTOS'!$AE$6:$AE$2005,'LANÇAMENTOS'!$AF$6:$AF$2005,"Faturamento Bruto",'LANÇAMENTOS'!$AA$6:$AA$2005,$B$7,'LANÇAMENTOS'!$Z$6:$Z$2005,IF($D$7=0,">0",$D$7),'LANÇAMENTOS'!$H$6:$H$2005,IF($F$7="Todos","*",$F$7),'LANÇAMENTOS'!$G$6:$G$2005,IF($H$7="Todos","*",$H$7),'LANÇAMENTOS'!$L$6:$L$2005,IF($J$7="Todos","*",$J$7),'LANÇAMENTOS'!$E$6:$E$2005,IF($L$7="Todos","*",$L$7)) | C131: Faturamento do período
B132: =SUMIFS('LANÇAMENTOS'!$AE$6:$AE$2005,'LANÇAMENTOS'!$AF$6:$AF$2005,"Impostos sobre Vendas",'LANÇAMENTOS'!$AA$6:$AA$2005,$B$7,'LANÇAMENTOS'!$Z$6:$Z$2005,IF($D$7=0,">0",$D$7),'LANÇAMENTOS'!$H$6:$H$2005,IF($F$7="Todos","*",$F$7),'LANÇAMENTOS'!$G$6:$G$2005,IF($H$7="Todos","*",$H$7),'LANÇAMENTOS'!$L$6:$L$2005,IF($J$7="Todos","*",$J$7),'LANÇAMENTOS'!$E$6:$E$2005,IF($L$7="Todos","*",$L$7))+SUMIFS('LANÇAMENTOS'!$AE$6:$AE$2005,'LANÇAMENTOS'!$AF$6:$AF$2005,"Devoluções",'LANÇAMENTOS'!$AA$6:$AA$2005,$B$7,'LANÇAMENTOS'!$Z$6:$Z$2005,IF($D$7=0,">0",$D$7),'LANÇAMENTOS'!$H$6:$H$2005,IF($F$7="Todos","*",$F$7),'LANÇAMENTOS'!$G$6:$G$2005,IF($H$7="Todos","*",$H$7),'LANÇAMENTOS'!$L$6:$L$2005,IF($J$7="Todos","*",$J$7),'LANÇAMENTOS'!$E$6:$E$2005,IF($L$7="Todos","*",$L$7)) | C132: Impostos e devoluções
B133: =SUMIFS('LANÇAMENTOS'!$AE$6:$AE$2005,'LANÇAMENTOS'!$AF$6:$AF$2005,"Custos Variáveis",'LANÇAMENTOS'!$AA$6:$AA$2005,$B$7,'LANÇAMENTOS'!$Z$6:$Z$2005,IF($D$7=0,">0",$D$7),'LANÇAMENTOS'!$H$6:$H$2005,IF($F$7="Todos","*",$F$7),'LANÇAMENTOS'!$G$6:$G$2005,IF($H$7="Todos","*",$H$7),'LANÇAMENTOS'!$L$6:$L$2005,IF($J$7="Todos","*",$J$7),'LANÇAMENTOS'!$E$6:$E$2005,IF($L$7="Todos","*",$L$7)) | C133: Custos variáveis
B134: =SUMIFS('LANÇAMENTOS'!$AE$6:$AE$2005,'LANÇAMENTOS'!$AF$6:$AF$2005,"Despesas Fixas",'LANÇAMENTOS'!$AA$6:$AA$2005,$B$7,'LANÇAMENTOS'!$Z$6:$Z$2005,IF($D$7=0,">0",$D$7),'LANÇAMENTOS'!$H$6:$H$2005,IF($F$7="Todos","*",$F$7),'LANÇAMENTOS'!$G$6:$G$2005,IF($H$7="Todos","*",$H$7),'LANÇAMENTOS'!$L$6:$L$2005,IF($J$7="Todos","*",$J$7),'LANÇAMENTOS'!$E$6:$E$2005,IF($L$7="Todos","*",$L$7)) | C134: Despesas fixas
B135: =SUMIFS('LANÇAMENTOS'!$AE$6:$AE$2005,'LANÇAMENTOS'!$AF$6:$AF$2005,"Despesas Financeiras",'LANÇAMENTOS'!$AA$6:$AA$2005,$B$7,'LANÇAMENTOS'!$Z$6:$Z$2005,IF($D$7=0,">0",$D$7),'LANÇAMENTOS'!$H$6:$H$2005,IF($F$7="Todos","*",$F$7),'LANÇAMENTOS'!$G$6:$G$2005,IF($H$7="Todos","*",$H$7),'LANÇAMENTOS'!$L$6:$L$2005,IF($J$7="Todos","*",$J$7),'LANÇAMENTOS'!$E$6:$E$2005,IF($L$7="Todos","*",$L$7)) | C135: Despesas financeiras
B136: =$B$131-$B$132 | C136: Receita líquida
B137: =SUMIFS('LANÇAMENTOS'!$AE$6:$AE$2005,'LANÇAMENTOS'!$AF$6:$AF$2005,"Receitas Financeiras",'LANÇAMENTOS'!$AA$6:$AA$2005,$B$7,'LANÇAMENTOS'!$Z$6:$Z$2005,IF($D$7=0,">0",$D$7),'LANÇAMENTOS'!$H$6:$H$2005,IF($F$7="Todos","*",$F$7),'LANÇAMENTOS'!$G$6:$G$2005,IF($H$7="Todos","*",$H$7),'LANÇAMENTOS'!$L$6:$L$2005,IF($J$7="Todos","*",$J$7),'LANÇAMENTOS'!$E$6:$E$2005,IF($L$7="Todos","*",$L$7))+SUMIFS('LANÇAMENTOS'!$AE$6:$AE$2005,'LANÇAMENTOS'!$AF$6:$AF$2005,"Outras Receitas Operacionais",'LANÇAMENTOS'!$AA$6:$AA$2005,$B$7,'LANÇAMENTOS'!$Z$6:$Z$2005,IF($D$7=0,">0",$D$7),'LANÇAMENTOS'!$H$6:$H$2005,IF($F$7="Todos","*",$F$7),'LANÇAMENTOS'!$G$6:$G$2005,IF($H$7="Todos","*",$H$7),'LANÇAMENTOS'!$L$6:$L$2005,IF($J$7="Todos","*",$J$7),'LANÇAMENTOS'!$E$6:$E$2005,IF($L$7="Todos","*",$L$7)) | C137: Receitas financeiras e outras
B138: =SUMIFS('LANÇAMENTOS'!$AE$6:$AE$2005,'LANÇAMENTOS'!$AF$6:$AF$2005,"Impostos sobre o Resultado",'LANÇAMENTOS'!$AA$6:$AA$2005,$B$7,'LANÇAMENTOS'!$Z$6:$Z$2005,IF($D$7=0,">0",$D$7),'LANÇAMENTOS'!$H$6:$H$2005,IF($F$7="Todos","*",$F$7),'LANÇAMENTOS'!$G$6:$G$2005,IF($H$7="Todos","*",$H$7),'LANÇAMENTOS'!$L$6:$L$2005,IF($J$7="Todos","*",$J$7),'LANÇAMENTOS'!$E$6:$E$2005,IF($L$7="Todos","*",$L$7)) | C138: Impostos sobre o lucro
B139: =IFERROR(($B$136-$B$133)/$B$136,"") | C139: Margem de contribuição %
B140: =$B$136-$B$133-$B$134-$B$135+$B$137-$B$138 | C140: Lucro líquido
B141: =IFERROR($B$140/$B$136,"") | C141: Margem líquida %
B142: =SUMIFS('LANÇAMENTOS'!$V$6:$V$2005,'LANÇAMENTOS'!$E$6:$E$2005,"Entrada",'LANÇAMENTOS'!$D$6:$D$2005,">="&DATE($B$7,IF($D$7=0,1,$D$7),1),'LANÇAMENTOS'!$D$6:$D$2005,"<="&IF($D$7=0,DATE($B$7,12,31),EOMONTH(DATE($B$7,$D$7,1),0)),'LANÇAMENTOS'!$H$6:$H$2005,IF($F$7="Todos","*",$F$7),'LANÇAMENTOS'!$G$6:$G$2005,IF($H$7="Todos","*",$H$7),'LANÇAMENTOS'!$L$6:$L$2005,IF($J$7="Todos","*",$J$7)) | C142: Entradas de caixa
B143: =SUMIFS('LANÇAMENTOS'!$V$6:$V$2005,'LANÇAMENTOS'!$E$6:$E$2005,"Saída",'LANÇAMENTOS'!$D$6:$D$2005,">="&DATE($B$7,IF($D$7=0,1,$D$7),1),'LANÇAMENTOS'!$D$6:$D$2005,"<="&IF($D$7=0,DATE($B$7,12,31),EOMONTH(DATE($B$7,$D$7,1),0)),'LANÇAMENTOS'!$H$6:$H$2005,IF($F$7="Todos","*",$F$7),'LANÇAMENTOS'!$G$6:$G$2005,IF($H$7="Todos","*",$H$7),'LANÇAMENTOS'!$L$6:$L$2005,IF($J$7="Todos","*",$J$7)) | C143: Saídas de caixa
...

Sheet CONFIGURAÇÕES
A1: CONFIGURAÇÕES DO SISTEMA FINANCEIRO
A2: Passo 1 do roteiro: informe os dados da empresa, as metas e os parâmetros. As listas auxiliares (colunas F a X) alimentam todos os menus suspensos da planilha.
A4: 1. IDENTIFICAÇÃO DA EMPRESA
A5: Razão social | B5: AURORA COMÉRCIO DE ALIMENTOS LTDA | E5: Empresa demonstrativa (dados fictícios)
A6: Nome fantasia | B6: Aurora Distribuidora
A7: CNPJ | B7: 12.345.678/0001-90
A8: Segmento de atuação | B8: Distribuição de alimentos e bebidas para revenda
A9: Regime tributário | B9: Simples Nacional | E9: Define o tratamento dos tributos
A10: Responsável financeiro | B10: Jefferson Andrade
A11: E-mail | B11: financeiro@auroradistribuidora.com.br
A12: Telefone | B12: (11) 4002-8922
A14: 2. PERÍODO DE REFERÊNCIA E FILTROS
A15: Data de referência (HOJE — automática) | B15: =TODAY() | E15: Todas as classificações automáticas (vencido, vence hoje, dias em atraso) usam esta data. | G15: Ano/mês de análise
A16: Ano atual | B16: =YEAR($B$15) | G16: B18 e B19 são os parâmetros usados pelo Dashboard e pelas análises.
A17: Mês atual | B17: =MONTH($B$15)
A18: Ano de análise (usado no Dashboard, DRE e relatórios) | B18: 2026
A19: Mês de análise (1 a 12 — 0 = todos os meses) | B19: 9
A21: 3. METAS E PARÂMETROS FINANCEIROS
A22: Meta de faturamento mensal | B22: 230000 | E22: Usada nos alertas de meta de faturamento e no orçamento.
A23: Meta de lucro líquido mensal | B23: 20000 | E23: Base do alerta de meta de lucro.
A24: Margem líquida mínima desejada | B24: 0.1 | E24: Margem abaixo deste valor gera alerta amarelo/vermelho.
A25: Saldo mínimo de caixa | B25: 30000 | E25: Alerta vermelho quando o saldo disponível ficar abaixo deste valor.
A26: Percentual máximo de inadimplência | B26: 0.05 | E26: Alerta quando o vencido a receber superar este percentual.
A27: Prazo médio de recebimento — alvo (dias) | B27: 30 | E27: Compare com o prazo médio real apurado na aba CONTAS A RECEBER.
A28: Prazo médio de pagamento — alvo (dias) | B28: 30 | E28: Compare com o prazo médio real apurado na aba CONTAS A PAGAR.
A29: Alíquota efetiva de impostos sobre vendas | B29: 0.085 | E29: Usada no Simples Nacional, no ponto de equilíbrio e no simulador de cenários.
A30: Taxa de juros mensal padrão (empréstimos) | B30: 0.014 | E30: Sugestão para novos contratos de crédito.
A31: Meta de crescimento mensal do faturamento | B31: 0.02 | E31: Usada na projeção de cenários.
A32: Reserva mínima de capital de giro (meses de despesa fixa) | B32: 2 | E32: Saldo recomendado = reserva × despesas fixas mensais.
A33: 4. LISTAS AUXILIARES — ALIMENTAM OS MENUS SUSPENSOS (para incluir um item, insira uma linha dentro da lista)
F34: Tipo de lançamento | G34: Situação | H34: Forma de pagamento | I34: Tipo de conta | J34: Status (cliente/fornecedor) | K34: Periodicidade | L34: Sistema de amortização | M34: Tipo de fluxo | N34: Bandeira do cartão | O34: Conciliação bancária | P34: Sim / Não | Q34: Regime tributário | R34: UF | S34: Meses | T34: Tipo de operação | U34: Categoria (grupo do plano de contas) | V34: Status do contrato | W34: Linhas do DRE
F36: Entrada | G36: Previsto | H36: Dinheiro | I36: Receita | J36: Ativo | K36: Mensal | L36: PRICE | M36: Operacional | N36: Visa | O36: Conciliado | P36: Sim | Q36: Simples Nacional | R36: AC | S36: Janeiro | T36: Todos | U36: Vendas | V36: Em andamento | W36: Faturamento Bruto
F37: Saída | G37: Pago | H37: PIX | I37: Custo | J37: Inativo | K37: Bimestral | L37: SAC | M37: Investimento | N37: Mastercard | O37: Pendente | P37: Não | Q37: MEI | R37: AL | S37: Fevereiro | T37: Entrada | U37: Outras Receitas | V37: Quitado | W37: Impostos sobre Vendas
G38: Recebido | H38: Transferência | I38: Despesa | J38: Bloqueado | K38: Trimestral | M38: Financiamento | N38: Elo | O38: Divergente | Q38: Lucro Presumido | R38: AM | S38: Março | T38: Saída | U38: Receitas Financeiras | V38: Renegociado | W38: Devoluções
G39: Vencido | H39: Boleto | I39: Imposto | K39: Semestral | N39: American Express | Q39: Lucro Real | R39: AP | S39: Abril | U39: Devoluções e Cancelamentos | V39: Em atraso | W39: Custos Variáveis
G40: Cancelado | H40: Cartão de débito | I40: Investimento | K40: Anual | N40: Hipercard | R40: BA | S40: Maio | U40: Custos Variáveis | W40: Despesas Fixas
G41: Parcial | H41: Cartão de crédito | I41: Pró-labore | N41: Outros | R41: CE | S41: Junho | U41: Despesas Administrativas | W41: Despesas Financeiras
H42: Crédito parcelado | I42: Empréstimo | R42: DF | S42: Julho | U42: Despesas com Pessoal | W42: Receitas Financeiras
H43: Débito automático | I43: Devolução | R43: ES | S43: Agosto | U43: Despesas Comerciais | W43: Outras Receitas Operacionais
H44: Outros | I44: Aporte de Capital | R44: GO | S44: Setembro | U44: Despesas Financeiras | W44: Impostos sobre o Resultado
...

Sheet CADASTRO DE CLIENTES
A1: CADASTRO DE CLIENTES
A2: Preencha as colunas amarelas. As colunas cinzas (P a W) são calculadas automaticamente a partir da aba LANÇAMENTOS — mantenha a razão social idêntica à usada nos lançamentos.
B4: ⚠ DADOS DE EXEMPLO — os clientes abaixo são fictícios. Substitua pelos seus clientes reais.
A5: Código | B5: Razão social | C5: Nome fantasia | D5: CPF/CNPJ | E5: Telefone | F5: WhatsApp | G5: E-mail | H5: Cidade | I5: UF | J5: Segmento | K5: Vendedor | L5: Limite de crédito | M5: Data de cadastro | N5: Status | O5: Observações | P5: Total comprado | Q5: Qtd. de compras | R5: Ticket médio | S5: Última compra | T5: Valor em aberto | U5: Valor vencido | V5: Dias em atraso (maior) | W5: Situação
A6: CLI001 | B6: MERCADO BOA COMPRA LTDA | C6: Boa Compra Supermercados | D6: 12.345.678/0001-11 | E6: (11) 3456-7890 | F6: (11) 99876-5432 | G6: compras@boacompra.com.br | H6: São Paulo | I6: SP | J6: Supermercados | K6: Carlos Menezes | L6: 90000 | M6: 44997 | N6: Ativo | O6: Cliente âncora — pedidos semanais, boleto 30 dias | P6: =IF($B6="","",SUMIFS('LANÇAMENTOS'!$Q$6:$Q$2005,'LANÇAMENTOS'!$I$6:$I$2005,$B6)+IF($C6=$B6,0,SUMIFS('LANÇAMENTOS'!$Q$6:$Q$2005,'LANÇAMENTOS'!$I$6:$I$2005,$C6))) | Q6: =IF($B6="","",COUNTIFS('LANÇAMENTOS'!$I$6:$I$2005,$B6,'LANÇAMENTOS'!$P$6:$P$2005,1)+IF($C6=$B6,0,COUNTIFS('LANÇAMENTOS'!$I$6:$I$2005,$C6,'LANÇAMENTOS'!$P$6:$P$2005,1))) | R6: =IFERROR(IF($P6=0,"",$P6/$Q6),"") | S6: =IF($B6="","",IFERROR(IF(SUMPRODUCT(MAX(('LANÇAMENTOS'!$I$6:$I$2005=$B6)*'LANÇAMENTOS'!$B$6:$B$2005))>0,SUMPRODUCT(MAX(('LANÇAMENTOS'!$I$6:$I$2005=$B6)*'LANÇAMENTOS'!$B$6:$B$2005)),""),"")) | T6: =IF($B6="","",SUMIFS('LANÇAMENTOS'!$W$6:$W$2005,'LANÇAMENTOS'!$I$6:$I$2005,$B6,'LANÇAMENTOS'!$E$6:$E$2005,"Entrada")+IF($C6=$B6,0,SUMIFS('LANÇAMENTOS'!$W$6:$W$2005,'LANÇAMENTOS'!$I$6:$I$2005,$C6,'LANÇAMENTOS'!$E$6:$E$2005,"Entrada"))) | U6: =IF($B6="","",SUMIFS('LANÇAMENTOS'!$W$6:$W$2005,'LANÇAMENTOS'!$I$6:$I$2005,$B6,'LANÇAMENTOS'!$E$6:$E$2005,"Entrada",'LANÇAMENTOS'!$C$6:$C$2005,"<"&TODAY())+IF($C6=$B6,0,SUMIFS('LANÇAMENTOS'!$W$6:$W$2005,'LANÇAMENTOS'!$I$6:$I$2005,$C6,'LANÇAMENTOS'!$E$6:$E$2005,"Entrada",'LANÇAMENTOS'!$C$6:$C$2005,"<"&TODAY()))) | V6: =IF(OR($B6="",$U6=0),0,MAX(0,TODAY()-IFERROR(-SUMPRODUCT(MAX(('LANÇAMENTOS'!$I$6:$I$2005=$B6)*('LANÇAMENTOS'!$W$6:$W$2005>0)*('LANÇAMENTOS'!$C$6:$C$2005<TODAY())*(-'LANÇAMENTOS'!$C$6:$C$2005))),TODAY()))) | W6: =IF($B6="","",IF($N6="Bloqueado","⛔ Bloqueado",IF($U6>0,"⚠ Com valores vencidos","✔ Em dia")))
A7: CLI002 | B7: PADARIA PÃO DOURADO ME | C7: Pão Dourado | D7: 22.456.789/0001-22 | E7: (11) 2765-4321 | F7: (11) 99765-1122 | G7: financeiro@paodourado.com.br | H7: Santo André | I7: SP | J7: Padarias | K7: Ana Paula Souza | L7: 30000 | M7: 45446 | N7: Ativo | O7: Pagamento à vista (PIX) na entrega | P7: =IF($B7="","",SUMIFS('LANÇAMENTOS'!$Q$6:$Q$2005,'LANÇAMENTOS'!$I$6:$I$2005,$B7)+IF($C7=$B7,0,SUMIFS('LANÇAMENTOS'!$Q$6:$Q$2005,'LANÇAMENTOS'!$I$6:$I$2005,$C7))) | Q7: =IF($B7="","",COUNTIFS('LANÇAMENTOS'!$I$6:$I$2005,$B7,'LANÇAMENTOS'!$P$6:$P$2005,1)+IF($C7=$B7,0,COUNTIFS('LANÇAMENTOS'!$I$6:$I$2005,$C7,'LANÇAMENTOS'!$P$6:$P$2005,1))) | R7: =IFERROR(IF($P7=0,"",$P7/$Q7),"") | S7: =IF($B7="","",IFERROR(IF(SUMPRODUCT(MAX(('LANÇAMENTOS'!$I$6:$I$2005=$B7)*'LANÇAMENTOS'!$B$6:$B$2005))>0,SUMPRODUCT(MAX(('LANÇAMENTOS'!$I$6:$I$2005=$B7)*'LANÇAMENTOS'!$B$6:$B$2005)),""),"")) | T7: =IF($B7="","",SUMIFS('LANÇAMENTOS'!$W$6:$W$2005,'LANÇAMENTOS'!$I$6:$I$2005,$B7,'LANÇAMENTOS'!$E$6:$E$2005,"Entrada")+IF($C7=$B7,0,SUMIFS('LANÇAMENTOS'!$W$6:$W$2005,'LANÇAMENTOS'!$I$6:$I$2005,$C7,'LANÇAMENTOS'!$E$6:$E$2005,"Entrada"))) | U7: =IF($B7="","",SUMIFS('LANÇAMENTOS'!$W$6:$W$2005,'LANÇAMENTOS'!$I$6:$I$2005,$B7,'LANÇAMENTOS'!$E$6:$E$2005,"Entrada",'LANÇAMENTOS'!$C$6:$C$2005,"<"&TODAY())+IF($C7=$B7,0,SUMIFS('LANÇAMENTOS'!$W$6:$W$2005,'LANÇAMENTOS'!$I$6:$I$2005,$C7,'LANÇAMENTOS'!$E$6:$E$2005,"Entrada",'LANÇAMENTOS'!$C$6:$C$2005,"<"&TODAY()))) | V7: =IF(OR($B7="",$U7=0),0,MAX(0,TODAY()-IFERROR(-SUMPRODUCT(MAX(('LANÇAMENTOS'!$I$6:$I$2005=$B7)*('LANÇAMENTOS'!$W$6:$W$2005>0)*('LANÇAMENTOS'!$C$6:$C$2005<TODAY())*(-'LANÇAMENTOS'!$C$6:$C$2005))),TODAY()))) | W7: =IF($B7="","",IF($N7="Bloqueado","⛔ Bloqueado",IF($U7>0,"⚠ Com valores vencidos","✔ Em dia")))
A8: CLI003 | B8: RESTAURANTE SABOR CASEIRO LTDA | C8: Sabor Caseiro | D8: 33.567.890/0001-33 | E8: (11) 3322-1100 | F8: (11) 99654-7788 | G8: contato@saborcaseiro.com.br | H8: São Paulo | I8: SP | J8: Restaurantes | K8: Carlos Menezes | L8: 45000 | M8: 45250 | N8: Ativo | O8: Entrega 2x por semana, boleto 15 dias | P8: =IF($B8="","",SUMIFS('LANÇAMENTOS'!$Q$6:$Q$2005,'LANÇAMENTOS'!$I$6:$I$2005,$B8)+IF($C8=$B8,0,SUMIFS('LANÇAMENTOS'!$Q$6:$Q$2005,'LANÇAMENTOS'!$I$6:$I$2005,$C8))) | Q8: =IF($B8="","",COUNTIFS('LANÇAMENTOS'!$I$6:$I$2005,$B8,'LANÇAMENTOS'!$P$6:$P$2005,1)+IF($C8=$B8,0,COUNTIFS('LANÇAMENTOS'!$I$6:$I$2005,$C8,'LANÇAMENTOS'!$P$6:$P$2005,1))) | R8: =IFERROR(IF($P8=0,"",$P8/$Q8),"") | S8: =IF($B8="","",IFERROR(IF(SUMPRODUCT(MAX(('LANÇAMENTOS'!$I$6:$I$2005=$B8)*'LANÇAMENTOS'!$B$6:$B$2005))>0,SUMPRODUCT(MAX(('LANÇAMENTOS'!$I$6:$I$2005=$B8)*'LANÇAMENTOS'!$B$6:$B$2005)),""),"")) | T8: =IF($B8="","",SUMIFS('LANÇAMENTOS'!$W$6:$W$2005,'LANÇAMENTOS'!$I$6:$I$2005,$B8,'LANÇAMENTOS'!$E$6:$E$2005,"Entrada")+IF($C8=$B8,0,SUMIFS('LANÇAMENTOS'!$W$6:$W$2005,'LANÇAMENTOS'!$I$6:$I$2005,$C8,'LANÇAMENTOS'!$E$6:$E$2005,"Entrada"))) | U8: =IF($B8="","",SUMIFS('LANÇAMENTOS'!$W$6:$W$2005,'LANÇAMENTOS'!$I$6:$I$2005,$B8,'LANÇAMENTOS'!$E$6:$E$2005,"Entrada",'LANÇAMENTOS'!$C$6:$C$2005,"<"&TODAY())+IF($C8=$B8,0,SUMIFS('LANÇAMENTOS'!$W$6:$W$2005,'LANÇAMENTOS'!$I$6:$I$2005,$C8,'LANÇAMENTOS'!$E$6:$E$2005,"Entrada",'LANÇAMENTOS'!$C$6:$C$2005,"<"&TODAY()))) | V8: =IF(OR($B8="",$U8=0),0,MAX(0,TODAY()-IFERROR(-SUMPRODUCT(MAX(('LANÇAMENTOS'!$I$6:$I$2005=$B8)*('LANÇAMENTOS'!$W$6:$W$2005>0)*('LANÇAMENTOS'!$C$6:$C$2005<TODAY())*(-'LANÇAMENTOS'!$C$6:$C$2005))),TODAY()))) | W8: =IF($B8="","",IF($N8="Bloqueado","⛔ Bloqueado",IF($U8>0,"⚠ Com valores vencidos","✔ Em dia")))
A9: CLI004 | B9: HOTEL VISTA ALEGRE LTDA | C9: Hotel Vista Alegre | D9: 44.678.901/0001-44 | E9: (11) 2222-3344 | F9: (11) 99555-2211 | G9: compras@vistaalegrehotel.com.br | H9: Guarulhos | I9: SP | J9: Hotelaria | K9: Ana Paula Souza | L9: 50000 | M9: 45306 | N9: Bloqueado | O9: INADIMPLENTE — 3 faturas vencidas; bloqueado para novas vendas a prazo | P9: =IF($B9="","",SUMIFS('LANÇAMENTOS'!$Q$6:$Q$2005,'LANÇAMENTOS'!$I$6:$I$2005,$B9)+IF($C9=$B9,0,SUMIFS('LANÇAMENTOS'!$Q$6:$Q$2005,'LANÇAMENTOS'!$I$6:$I$2005,$C9))) | Q9: =IF($B9="","",COUNTIFS('LANÇAMENTOS'!$I$6:$I$2005,$B9,'LANÇAMENTOS'!$P$6:$P$2005,1)+IF($C9=$B9,0,COUNTIFS('LANÇAMENTOS'!$I$6:$I$2005,$C9,'LANÇAMENTOS'!$P$6:$P$2005,1))) | R9: =IFERROR(IF($P9=0,"",$P9/$Q9),"") | S9: =IF($B9="","",IFERROR(IF(SUMPRODUCT(MAX(('LANÇAMENTOS'!$I$6:$I$2005=$B9)*'LANÇAMENTOS'!$B$6:$B$2005))>0,SUMPRODUCT(MAX(('LANÇAMENTOS'!$I$6:$I$2005=$B9)*'LANÇAMENTOS'!$B$6:$B$2005)),""),"")) | T9: =IF($B9="","",SUMIFS('LANÇAMENTOS'!$W$6:$W$2005,'LANÇAMENTOS'!$I$6:$I$2005,$B9,'LANÇAMENTOS'!$E$6:$E$2005,"Entrada")+IF($C9=$B9,0,SUMIFS('LANÇAMENTOS'!$W$6:$W$2005,'LANÇAMENTOS'!$I$6:$I$2005,$C9,'LANÇAMENTOS'!$E$6:$E$2005,"Entrada"))) | U9: =IF($B9="","",SUMIFS('LANÇAMENTOS'!$W$6:$W$2005,'LANÇAMENTOS'!$I$6:$I$2005,$B9,'LANÇAMENTOS'!$E$6:$E$2005,"Entrada",'LANÇAMENTOS'!$C$6:$C$2005,"<"&TODAY())+IF($C9=$B9,0,SUMIFS('LANÇAMENTOS'!$W$6:$W$2005,'LANÇAMENTOS'!$I$6:$I$2005,$C9,'LANÇAMENTOS'!$E$6:$E$2005,"Entrada",'LANÇAMENTOS'!$C$6:$C$2005,"<"&TODAY()))) | V9: =IF(OR($B9="",$U9=0),0,MAX(0,TODAY()-IFERROR(-SUMPRODUCT(MAX(('LANÇAMENTOS'!$I$6:$I$2005=$B9)*('LANÇAMENTOS'!$W$6:$W$2005>0)*('LANÇAMENTOS'!$C$6:$C$2005<TODAY())*(-'LANÇAMENTOS'!$C$6:$C$2005))),TODAY()))) | W9: =IF($B9="","",IF($N9="Bloqueado","⛔ Bloqueado",IF($U9>0,"⚠ Com valores vencidos","✔ Em dia")))
A10: CLI005 | B10: EMPÓRIO NATURAL COMÉRCIO LTDA | C10: Empório Natural | D10: 55.789.012/0001-55 | E10: (11) 4002-7788 | F10: (11) 99444-3322 | G10: suprimentos@emporionatural.com.br | H10: Osasco | I10: SP | J10: Varejo de Alimentos | K10: Carlos Menezes | L10: 60000 | M10: 45543 | N10: Ativo | O10: Compras parceladas em 2x/3x — acompanhar limite | P10: =IF($B10="","",SUMIFS('LANÇAMENTOS'!$Q$6:$Q$2005,'LANÇAMENTOS'!$I$6:$I$2005,$B10)+IF($C10=$B10,0,SUMIFS('LANÇAMENTOS'!$Q$6:$Q$2005,'LANÇAMENTOS'!$I$6:$I$2005,$C10))) | Q10: =IF($B10="","",COUNTIFS('LANÇAMENTOS'!$I$6:$I$2005,$B10,'LANÇAMENTOS'!$P$6:$P$2005,1)+IF($C10=$B10,0,COUNTIFS('LANÇAMENTOS'!$I$6:$I$2005,$C10,'LANÇAMENTOS'!$P$6:$P$2005,1))) | R10: =IFERROR(IF($P10=0,"",$P10/$Q10),"") | S10: =IF($B10="","",IFERROR(IF(SUMPRODUCT(MAX(('LANÇAMENTOS'!$I$6:$I$2005=$B10)*'LANÇAMENTOS'!$B$6:$B$2005))>0,SUMPRODUCT(MAX(('LANÇAMENTOS'!$I$6:$I$2005=$B10)*'LANÇAMENTOS'!$B$6:$B$2005)),""),"")) | T10: =IF($B10="","",SUMIFS('LANÇAMENTOS'!$W$6:$W$2005,'LANÇAMENTOS'!$I$6:$I$2005,$B10,'LANÇAMENTOS'!$E$6:$E$2005,"Entrada")+IF($C10=$B10,0,SUMIFS('LANÇAMENTOS'!$W$6:$W$2005,'LANÇAMENTOS'!$I$6:$I$2005,$C10,'LANÇAMENTOS'!$E$6:$E$2005,"Entrada"))) | U10: =IF($B10="","",SUMIFS('LANÇAMENTOS'!$W$6:$W$2005,'LANÇAMENTOS'!$I$6:$I$2005,$B10,'LANÇAMENTOS'!$E$6:$E$2005,"Entrada",'LANÇAMENTOS'!$C$6:$C$2005,"<"&TODAY())+IF($C10=$B10,0,SUMIFS('LANÇAMENTOS'!$W$6:$W$2005,'LANÇAMENTOS'!$I$6:$I$2005,$C10,'LANÇAMENTOS'!$E$6:$E$2005,"Entrada",'LANÇAMENTOS'!$C$6:$C$2005,"<"&TODAY()))) | V10: =IF(OR($B10="",$U10=0),0,MAX(0,TODAY()-IFERROR(-SUMPRODUCT(MAX(('LANÇAMENTOS'!$I$6:$I$2005=$B10)*('LANÇAMENTOS'!$W$6:$W$2005>0)*('LANÇAMENTOS'!$C$6:$C$2005<TODAY())*(-'LANÇAMENTOS'!$C$6:$C$2005))),TODAY()))) | W10: =IF($B10="","",IF($N10="Bloqueado","⛔ Bloqueado",IF($U10>0,"⚠ Com valores vencidos","✔ Em dia")))
P11: =IF($B11="","",SUMIFS('LANÇAMENTOS'!$Q$6:$Q$2005,'LANÇAMENTOS'!$I$6:$I$2005,$B11)+IF($C11=$B11,0,SUMIFS('LANÇAMENTOS'!$Q$6:$Q$2005,'LANÇAMENTOS'!$I$6:$I$2005,$C11))) | Q11: =IF($B11="","",COUNTIFS('LANÇAMENTOS'!$I$6:$I$2005,$B11,'LANÇAMENTOS'!$P$6:$P$2005,1)+IF($C11=$B11,0,COUNTIFS('LANÇAMENTOS'!$I$6:$I$2005,$C11,'LANÇAMENTOS'!$P$6:$P$2005,1))) | R11: =IFERROR(IF($P11=0,"",$P11/$Q11),"") | S11: =IF($B11="","",IFERROR(IF(SUMPRODUCT(MAX(('LANÇAMENTOS'!$I$6:$I$2005=$B11)*'LANÇAMENTOS'!$B$6:$B$2005))>0,SUMPRODUCT(MAX(('LANÇAMENTOS'!$I$6:$I$2005=$B11)*'LANÇAMENTOS'!$B$6:$B$2005)),""),"")) | T11: =IF($B11="","",SUMIFS('LANÇAMENTOS'!$W$6:$W$2005,'LANÇAMENTOS'!$I$6:$I$2005,$B11,'LANÇAMENTOS'!$E$6:$E$2005,"Entrada")+IF($C11=$B11,0,SUMIFS('LANÇAMENTOS'!$W$6:$W$2005,'LANÇAMENTOS'!$I$6:$I$2005,$C11,'LANÇAMENTOS'!$E$6:$E$2005,"Entrada"))) | U11: =IF($B11="","",SUMIFS('LANÇAMENTOS'!$W$6:$W$2005,'LANÇAMENTOS'!$I$6:$I$2005,$B11,'LANÇAMENTOS'!$E$6:$E$2005,"Entrada",'LANÇAMENTOS'!$C$6:$C$2005,"<"&TODAY())+IF($C11=$B11,0,SUMIFS('LANÇAMENTOS'!$W$6:$W$2005,'LANÇAMENTOS'!$I$6:$I$2005,$C11,'LANÇAMENTOS'!$E$6:$E$2005,"Entrada",'LANÇAMENTOS'!$C$6:$C$2005,"<"&TODAY()))) | V11: =IF(OR($B11="",$U11=0),0,MAX(0,TODAY()-IFERROR(-SUMPRODUCT(MAX(('LANÇAMENTOS'!$I$6:$I$2005=$B11)*('LANÇAMENTOS'!$W$6:$W$2005>0)*('LANÇAMENTOS'!$C$6:$C$2005<TODAY())*(-'LANÇAMENTOS'!$C$6:$C$2005))),TODAY()))) | W11: =IF($B11="","",IF($N11="Bloqueado","⛔ Bloqueado",IF($U11>0,"⚠ Com valores vencidos","✔ Em dia")))
P12: =IF($B12="","",SUMIFS('LANÇAMENTOS'!$Q$6:$Q$2005,'LANÇAMENTOS'!$I$6:$I$2005,$B12)+IF($C12=$B12,0,SUMIFS('LANÇAMENTOS'!$Q$6:$Q$2005,'LANÇAMENTOS'!$I$6:$I$2005,$C12))) | Q12: =IF($B12="","",COUNTIFS('LANÇAMENTOS'!$I$6:$I$2005,$B12,'LANÇAMENTOS'!$P$6:$P$2005,1)+IF($C12=$B12,0,COUNTIFS('LANÇAMENTOS'!$I$6:$I$2005,$C12,'LANÇAMENTOS'!$P$6:$P$2005,1))) | R12: =IFERROR(IF($P12=0,"",$P12/$Q12),"") | S12: =IF($B12="","",IFERROR(IF(SUMPRODUCT(MAX(('LANÇAMENTOS'!$I$6:$I$2005=$B12)*'LANÇAMENTOS'!$B$6:$B$2005))>0,SUMPRODUCT(MAX(('LANÇAMENTOS'!$I$6:$I$2005=$B12)*'LANÇAMENTOS'!$B$6:$B$2005)),""),"")) | T12: =IF($B12="","",SUMIFS('LANÇAMENTOS'!$W$6:$W$2005,'LANÇAMENTOS'!$I$6:$I$2005,$B12,'LANÇAMENTOS'!$E$6:$E$2005,"Entrada")+IF($C12=$B12,0,SUMIFS('LANÇAMENTOS'!$W$6:$W$2005,'LANÇAMENTOS'!$I$6:$I$2005,$C12,'LANÇAMENTOS'!$E$6:$E$2005,"Entrada"))) | U12: =IF($B12="","",SUMIFS('LANÇAMENTOS'!$W$6:$W$2005,'LANÇAMENTOS'!$I$6:$I$2005,$B12,'LANÇAMENTOS'!$E$6:$E$2005,"Entrada",'LANÇAMENTOS'!$C$6:$C$2005,"<"&TODAY())+IF($C12=$B12,0,SUMIFS('LANÇAMENTOS'!$W$6:$W$2005,'LANÇAMENTOS'!$I$6:$I$2005,$C12,'LANÇAMENTOS'!$E$6:$E$2005,"Entrada",'LANÇAMENTOS'!$C$6:$C$2005,"<"&TODAY()))) | V12: =IF(OR($B12="",$U12=0),0,MAX(0,TODAY()-IFERROR(-SUMPRODUCT(MAX(('LANÇAMENTOS'!$I$6:$I$2005=$B12)*('LANÇAMENTOS'!$W$6:$W$2005>0)*('LANÇAMENTOS'!$C$6:$C$2005<TODAY())*(-'LANÇAMENTOS'!$C$6:$C$2005))),TODAY()))) | W12: =IF($B12="","",IF($N12="Bloqueado","⛔ Bloqueado",IF($U12>0,"⚠ Com valores vencidos","✔ Em dia")))
P13: =IF($B13="","",SUMIFS('LANÇAMENTOS'!$Q$6:$Q$2005,'LANÇAMENTOS'!$I$6:$I$2005,$B13)+IF($C13=$B13,0,SUMIFS('LANÇAMENTOS'!$Q$6:$Q$2005,'LANÇAMENTOS'!$I$6:$I$2005,$C13))) | Q13: =IF($B13="","",COUNTIFS('LANÇAMENTOS'!$I$6:$I$2005,$B13,'LANÇAMENTOS'!$P$6:$P$2005,1)+IF($C13=$B13,0,COUNTIFS('LANÇAMENTOS'!$I$6:$I$2005,$C13,'LANÇAMENTOS'!$P$6:$P$2005,1))) | R13: =IFERROR(IF($P13=0,"",$P13/$Q13),"") | S13: =IF($B13="","",IFERROR(IF(SUMPRODUCT(MAX(('LANÇAMENTOS'!$I$6:$I$2005=$B13)*'LANÇAMENTOS'!$B$6:$B$2005))>0,SUMPRODUCT(MAX(('LANÇAMENTOS'!$I$6:$I$2005=$B13)*'LANÇAMENTOS'!$B$6:$B$2005)),""),"")) | T13: =IF($B13="","",SUMIFS('LANÇAMENTOS'!$W$6:$W$2005,'LANÇAMENTOS'!$I$6:$I$2005,$B13,'LANÇAMENTOS'!$E$6:$E$2005,"Entrada")+IF($C13=$B13,0,SUMIFS('LANÇAMENTOS'!$W$6:$W$2005,'LANÇAMENTOS'!$I$6:$I$2005,$C13,'LANÇAMENTOS'!$E$6:$E$2005,"Entrada"))) | U13: =IF($B13="","",SUMIFS('LANÇAMENTOS'!$W$6:$W$2005,'LANÇAMENTOS'!$I$6:$I$2005,$B13,'LANÇAMENTOS'!$E$6:$E$2005,"Entrada",'LANÇAMENTOS'!$C$6:$C$2005,"<"&TODAY())+IF($C13=$B13,0,SUMIFS('LANÇAMENTOS'!$W$6:$W$2005,'LANÇAMENTOS'!$I$6:$I$2005,$C13,'LANÇAMENTOS'!$E$6:$E$2005,"Entrada",'LANÇAMENTOS'!$C$6:$C$2005,"<"&TODAY()))) | V13: =IF(OR($B13="",$U13=0),0,MAX(0,TODAY()-IFERROR(-SUMPRODUCT(MAX(('LANÇAMENTOS'!$I$6:$I$2005=$B13)*('LANÇAMENTOS'!$W$6:$W$2005>0)*('LANÇAMENTOS'!$C$6:$C$2005<TODAY())*(-'LANÇAMENTOS'!$C$6:$C$2005))),TODAY()))) | W13: =IF($B13="","",IF($N13="Bloqueado","⛔ Bloqueado",IF($U13>0,"⚠ Com valores vencidos","✔ Em dia")))
P14: =IF($B14="","",SUMIFS('LANÇAMENTOS'!$Q$6:$Q$2005,'LANÇAMENTOS'!$I$6:$I$2005,$B14)+IF($C14=$B14,0,SUMIFS('LANÇAMENTOS'!$Q$6:$Q$2005,'LANÇAMENTOS'!$I$6:$I$2005,$C14))) | Q14: =IF($B14="","",COUNTIFS('LANÇAMENTOS'!$I$6:$I$2005,$B14,'LANÇAMENTOS'!$P$6:$P$2005,1)+IF($C14=$B14,0,COUNTIFS('LANÇAMENTOS'!$I$6:$I$2005,$C14,'LANÇAMENTOS'!$P$6:$P$2005,1))) | R14: =IFERROR(IF($P14=0,"",$P14/$Q14),"") | S14: =IF($B14="","",IFERROR(IF(SUMPRODUCT(MAX(('LANÇAMENTOS'!$I$6:$I$2005=$B14)*'LANÇAMENTOS'!$B$6:$B$2005))>0,SUMPRODUCT(MAX(('LANÇAMENTOS'!$I$6:$I$2005=$B14)*'LANÇAMENTOS'!$B$6:$B$2005)),""),"")) | T14: =IF($B14="","",SUMIFS('LANÇAMENTOS'!$W$6:$W$2005,'LANÇAMENTOS'!$I$6:$I$2005,$B14,'LANÇAMENTOS'!$E$6:$E$2005,"Entrada")+IF($C14=$B14,0,SUMIFS('LANÇAMENTOS'!$W$6:$W$2005,'LANÇAMENTOS'!$I$6:$I$2005,$C14,'LANÇAMENTOS'!$E$6:$E$2005,"Entrada"))) | U14: =IF($B14="","",SUMIFS('LANÇAMENTOS'!$W$6:$W$2005,'LANÇAMENTOS'!$I$6:$I$2005,$B14,'LANÇAMENTOS'!$E$6:$E$2005,"Entrada",'LANÇAMENTOS'!$C$6:$C$2005,"<"&TODAY())+IF($C14=$B14,0,SUMIFS('LANÇAMENTOS'!$W$6:$W$2005,'LANÇAMENTOS'!$I$6:$I$2005,$C14,'LANÇAMENTOS'!$E$6:$E$2005,"Entrada",'LANÇAMENTOS'!$C$6:$C$2005,"<"&TODAY()))) | V14: =IF(OR($B14="",$U14=0),0,MAX(0,TODAY()-IFERROR(-SUMPRODUCT(MAX(('LANÇAMENTOS'!$I$6:$I$2005=$B14)*('LANÇAMENTOS'!$W$6:$W$2005>0)*('LANÇAMENTOS'!$C$6:$C$2005<TODAY())*(-'LANÇAMENTOS'!$C$6:$C$2005))),TODAY()))) | W14: =IF($B14="","",IF($N14="Bloqueado","⛔ Bloqueado",IF($U14>0,"⚠ Com valores vencidos","✔ Em dia")))
P15: =IF($B15="","",SUMIFS('LANÇAMENTOS'!$Q$6:$Q$2005,'LANÇAMENTOS'!$I$6:$I$2005,$B15)+IF($C15=$B15,0,SUMIFS('LANÇAMENTOS'!$Q$6:$Q$2005,'LANÇAMENTOS'!$I$6:$I$2005,$C15))) | Q15: =IF($B15="","",COUNTIFS('LANÇAMENTOS'!$I$6:$I$2005,$B15,'LANÇAMENTOS'!$P$6:$P$2005,1)+IF($C15=$B15,0,COUNTIFS('LANÇAMENTOS'!$I$6:$I$2005,$C15,'LANÇAMENTOS'!$P$6:$P$2005,1))) | R15: =IFERROR(IF($P15=0,"",$P15/$Q15),"") | S15: =IF($B15="","",IFERROR(IF(SUMPRODUCT(MAX(('LANÇAMENTOS'!$I$6:$I$2005=$B15)*'LANÇAMENTOS'!$B$6:$B$2005))>0,SUMPRODUCT(MAX(('LANÇAMENTOS'!$I$6:$I$2005=$B15)*'LANÇAMENTOS'!$B$6:$B$2005)),""),"")) | T15: =IF($B15="","",SUMIFS('LANÇAMENTOS'!$W$6:$W$2005,'LANÇAMENTOS'!$I$6:$I$2005,$B15,'LANÇAMENTOS'!$E$6:$E$2005,"Entrada")+IF($C15=$B15,0,SUMIFS('LANÇAMENTOS'!$W$6:$W$2005,'LANÇAMENTOS'!$I$6:$I$2005,$C15,'LANÇAMENTOS'!$E$6:$E$2005,"Entrada"))) | U15: =IF($B15="","",SUMIFS('LANÇAMENTOS'!$W$6:$W$2005,'LANÇAMENTOS'!$I$6:$I$2005,$B15,'LANÇAMENTOS'!$E$6:$E$2005,"Entrada",'LANÇAMENTOS'!$C$6:$C$2005,"<"&TODAY())+IF($C15=$B15,0,SUMIFS('LANÇAMENTOS'!$W$6:$W$2005,'LANÇAMENTOS'!$I$6:$I$2005,$C15,'LANÇAMENTOS'!$E$6:$E$2005,"Entrada",'LANÇAMENTOS'!$C$6:$C$2005,"<"&TODAY()))) | V15: =IF(OR($B15="",$U15=0),0,MAX(0,TODAY()-IFERROR(-SUMPRODUCT(MAX(('LANÇAMENTOS'!$I$6:$I$2005=$B15)*('LANÇAMENTOS'!$W$6:$W$2005>0)*('LANÇAMENTOS'!$C$6:$C$2005<TODAY())*(-'LANÇAMENTOS'!$C$6:$C$2005))),TODAY()))) | W15: =IF($B15="","",IF($N15="Bloqueado","⛔ Bloqueado",IF($U15>0,"⚠ Com valores vencidos","✔ Em dia")))
P16: =IF($B16="","",SUMIFS('LANÇAMENTOS'!$Q$6:$Q$2005,'LANÇAMENTOS'!$I$6:$I$2005,$B16)+IF($C16=$B16,0,SUMIFS('LANÇAMENTOS'!$Q$6:$Q$2005,'LANÇAMENTOS'!$I$6:$I$2005,$C16))) | Q16: =IF($B16="","",COUNTIFS('LANÇAMENTOS'!$I$6:$I$2005,$B16,'LANÇAMENTOS'!$P$6:$P$2005,1)+IF($C16=$B16,0,COUNTIFS('LANÇAMENTOS'!$I$6:$I$2005,$C16,'LANÇAMENTOS'!$P$6:$P$2005,1))) | R16: =IFERROR(IF($P16=0,"",$P16/$Q16),"") | S16: =IF($B16="","",IFERROR(IF(SUMPRODUCT(MAX(('LANÇAMENTOS'!$I$6:$I$2005=$B16)*'LANÇAMENTOS'!$B$6:$B$2005))>0,SUMPRODUCT(MAX(('LANÇAMENTOS'!$I$6:$I$2005=$B16)*'LANÇAMENTOS'!$B$6:$B$2005)),""),"")) | T16: =IF($B16="","",SUMIFS('LANÇAMENTOS'!$W$6:$W$2005,'LANÇAMENTOS'!$I$6:$I$2005,$B16,'LANÇAMENTOS'!$E$6:$E$2005,"Entrada")+IF($C16=$B16,0,SUMIFS('LANÇAMENTOS'!$W$6:$W$2005,'LANÇAMENTOS'!$I$6:$I$2005,$C16,'LANÇAMENTOS'!$E$6:$E$2005,"Entrada"))) | U16: =IF($B16="","",SUMIFS('LANÇAMENTOS'!$W$6:$W$2005,'LANÇAMENTOS'!$I$6:$I$2005,$B16,'LANÇAMENTOS'!$E$6:$E$2005,"Entrada",'LANÇAMENTOS'!$C$6:$C$2005,"<"&TODAY())+IF($C16=$B16,0,SUMIFS('LANÇAMENTOS'!$W$6:$W$2005,'LANÇAMENTOS'!$I$6:$I$2005,$C16,'LANÇAMENTOS'!$E$6:$E$2005,"Entrada",'LANÇAMENTOS'!$C$6:$C$2005,"<"&TODAY()))) | V16: =IF(OR($B16="",$U16=0),0,MAX(0,TODAY()-IFERROR(-SUMPRODUCT(MAX(('LANÇAMENTOS'!$I$6:$I$2005=$B16)*('LANÇAMENTOS'!$W$6:$W$2005>0)*('LANÇAMENTOS'!$C$6:$C$2005<TODAY())*(-'LANÇAMENTOS'!$C$6:$C$2005))),TODAY()))) | W16: =IF($B16="","",IF($N16="Bloqueado","⛔ Bloqueado",IF($U16>0,"⚠ Com valores vencidos","✔ Em dia")))
P17: =IF($B17="","",SUMIFS('LANÇAMENTOS'!$Q$6:$Q$2005,'LANÇAMENTOS'!$I$6:$I$2005,$B17)+IF($C17=$B17,0,SUMIFS('LANÇAMENTOS'!$Q$6:$Q$2005,'LANÇAMENTOS'!$I$6:$I$2005,$C17))) | Q17: =IF($B17="","",COUNTIFS('LANÇAMENTOS'!$I$6:$I$2005,$B17,'LANÇAMENTOS'!$P$6:$P$2005,1)+IF($C17=$B17,0,COUNTIFS('LANÇAMENTOS'!$I$6:$I$2005,$C17,'LANÇAMENTOS'!$P$6:$P$2005,1))) | R17: =IFERROR(IF($P17=0,"",$P17/$Q17),"") | S17: =IF($B17="","",IFERROR(IF(SUMPRODUCT(MAX(('LANÇAMENTOS'!$I$6:$I$2005=$B17)*'LANÇAMENTOS'!$B$6:$B$2005))>0,SUMPRODUCT(MAX(('LANÇAMENTOS'!$I$6:$I$2005=$B17)*'LANÇAMENTOS'!$B$6:$B$2005)),""),"")) | T17: =IF($B17="","",SUMIFS('LANÇAMENTOS'!$W$6:$W$2005,'LANÇAMENTOS'!$I$6:$I$2005,$B17,'LANÇAMENTOS'!$E$6:$E$2005,"Entrada")+IF($C17=$B17,0,SUMIFS('LANÇAMENTOS'!$W$6:$W$2005,'LANÇAMENTOS'!$I$6:$I$2005,$C17,'LANÇAMENTOS'!$E$6:$E$2005,"Entrada"))) | U17: =IF($B17="","",SUMIFS('LANÇAMENTOS'!$W$6:$W$2005,'LANÇAMENTOS'!$I$6:$I$2005,$B17,'LANÇAMENTOS'!$E$6:$E$2005,"Entrada",'LANÇAMENTOS'!$C$6:$C$2005,"<"&TODAY())+IF($C17=$B17,0,SUMIFS('LANÇAMENTOS'!$W$6:$W$2005,'LANÇAMENTOS'!$I$6:$I$2005,$C17,'LANÇAMENTOS'!$E$6:$E$2005,"Entrada",'LANÇAMENTOS'!$C$6:$C$2005,"<"&TODAY()))) | V17: =IF(OR($B17="",$U17=0),0,MAX(0,TODAY()-IFERROR(-SUMPRODUCT(MAX(('LANÇAMENTOS'!$I$6:$I$2005=$B17)*('LANÇAMENTOS'!$W$6:$W$2005>0)*('LANÇAMENTOS'!$C$6:$C$2005<TODAY())*(-'LANÇAMENTOS'!$C$6:$C$2005))),TODAY()))) | W17: =IF($B17="","",IF($N17="Bloqueado","⛔ Bloqueado",IF($U17>0,"⚠ Com valores vencidos","✔ Em dia")))
P18: =IF($B18="","",SUMIFS('LANÇAMENTOS'!$Q$6:$Q$2005,'LANÇAMENTOS'!$I$6:$I$2005,$B18)+IF($C18=$B18,0,SUMIFS('LANÇAMENTOS'!$Q$6:$Q$2005,'LANÇAMENTOS'!$I$6:$I$2005,$C18))) | Q18: =IF($B18="","",COUNTIFS('LANÇAMENTOS'!$I$6:$I$2005,$B18,'LANÇAMENTOS'!$P$6:$P$2005,1)+IF($C18=$B18,0,COUNTIFS('LANÇAMENTOS'!$I$6:$I$2005,$C18,'LANÇAMENTOS'!$P$6:$P$2005,1))) | R18: =IFERROR(IF($P18=0,"",$P18/$Q18),"") | S18: =IF($B18="","",IFERROR(IF(SUMPRODUCT(MAX(('LANÇAMENTOS'!$I$6:$I$2005=$B18)*'LANÇAMENTOS'!$B$6:$B$2005))>0,SUMPRODUCT(MAX(('LANÇAMENTOS'!$I$6:$I$2005=$B18)*'LANÇAMENTOS'!$B$6:$B$2005)),""),"")) | T18: =IF($B18="","",SUMIFS('LANÇAMENTOS'!$W$6:$W$2005,'LANÇAMENTOS'!$I$6:$I$2005,$B18,'LANÇAMENTOS'!$E$6:$E$2005,"Entrada")+IF($C18=$B18,0,SUMIFS('LANÇAMENTOS'!$W$6:$W$2005,'LANÇAMENTOS'!$I$6:$I$2005,$C18,'LANÇAMENTOS'!$E$6:$E$2005,"Entrada"))) | U18: =IF($B18="","",SUMIFS('LANÇAMENTOS'!$W$6:$W$2005,'LANÇAMENTOS'!$I$6:$I$2005,$B18,'LANÇAMENTOS'!$E$6:$E$2005,"Entrada",'LANÇAMENTOS'!$C$6:$C$2005,"<"&TODAY())+IF($C18=$B18,0,SUMIFS('LANÇAMENTOS'!$W$6:$W$2005,'LANÇAMENTOS'!$I$6:$I$2005,$C18,'LANÇAMENTOS'!$E$6:$E$2005,"Entrada",'LANÇAMENTOS'!$C$6:$C$2005,"<"&TODAY()))) | V18: =IF(OR($B18="",$U18=0),0,MAX(0,TODAY()-IFERROR(-SUMPRODUCT(MAX(('LANÇAMENTOS'!$I$6:$I$2005=$B18)*('LANÇAMENTOS'!$W$6:$W$2005>0)*('LANÇAMENTOS'!$C$6:$C$2005<TODAY())*(-'LANÇAMENTOS'!$C$6:$C$2005))),TODAY()))) | W18: =IF($B18="","",IF($N18="Bloqueado","⛔ Bloqueado",IF($U18>0,"⚠ Com valores vencidos","✔ Em dia")))
P19: =IF($B19="","",SUMIFS('LANÇAMENTOS'!$Q$6:$Q$2005,'LANÇAMENTOS'!$I$6:$I$2005,$B19)+IF($C19=$B19,0,SUMIFS('LANÇAMENTOS'!$Q$6:$Q$2005,'LANÇAMENTOS'!$I$6:$I$2005,$C19))) | Q19: =IF($B19="","",COUNTIFS('LANÇAMENTOS'!$I$6:$I$2005,$B19,'LANÇAMENTOS'!$P$6:$P$2005,1)+IF($C19=$B19,0,COUNTIFS('LANÇAMENTOS'!$I$6:$I$2005,$C19,'LANÇAMENTOS'!$P$6:$P$2005,1))) | R19: =IFERROR(IF($P19=0,"",$P19/$Q19),"") | S19: =IF($B19="","",IFERROR(IF(SUMPRODUCT(MAX(('LANÇAMENTOS'!$I$6:$I$2005=$B19)*'LANÇAMENTOS'!$B$6:$B$2005))>0,SUMPRODUCT(MAX(('LANÇAMENTOS'!$I$6:$I$2005=$B19)*'LANÇAMENTOS'!$B$6:$B$2005)),""),"")) | T19: =IF($B19="","",SUMIFS('LANÇAMENTOS'!$W$6:$W$2005,'LANÇAMENTOS'!$I$6:$I$2005,$B19,'LANÇAMENTOS'!$E$6:$E$2005,"Entrada")+IF($C19=$B19,0,SUMIFS('LANÇAMENTOS'!$W$6:$W$2005,'LANÇAMENTOS'!$I$6:$I$2005,$C19,'LANÇAMENTOS'!$E$6:$E$2005,"Entrada"))) | U19: =IF($B19="","",SUMIFS('LANÇAMENTOS'!$W$6:$W$2005,'LANÇAMENTOS'!$I$6:$I$2005,$B19,'LANÇAMENTOS'!$E$6:$E$2005,"Entrada",'LANÇAMENTOS'!$C$6:$C$2005,"<"&TODAY())+IF($C19=$B19,0,SUMIFS('LANÇAMENTOS'!$W$6:$W$2005,'LANÇAMENTOS'!$I$6:$I$2005,$C19,'LANÇAMENTOS'!$E$6:$E$2005,"Entrada",'LANÇAMENTOS'!$C$6:$C$2005,"<"&TODAY()))) | V19: =IF(OR($B19="",$U19=0),0,MAX(0,TODAY()-IFERROR(-SUMPRODUCT(MAX(('LANÇAMENTOS'!$I$6:$I$2005=$B19)*('LANÇAMENTOS'!$W$6:$W$2005>0)*('LANÇAMENTOS'!$C$6:$C$2005<TODAY())*(-'LANÇAMENTOS'!$C$6:$C$2005))),TODAY()))) | W19: =IF($B19="","",IF($N19="Bloqueado","⛔ Bloqueado",IF($U19>0,"⚠ Com valores vencidos","✔ Em dia")))
P20: =IF($B20="","",SUMIFS('LANÇAMENTOS'!$Q$6:$Q$2005,'LANÇAMENTOS'!$I$6:$I$2005,$B20)+IF($C20=$B20,0,SUMIFS('LANÇAMENTOS'!$Q$6:$Q$2005,'LANÇAMENTOS'!$I$6:$I$2005,$C20))) | Q20: =IF($B20="","",COUNTIFS('LANÇAMENTOS'!$I$6:$I$2005,$B20,'LANÇAMENTOS'!$P$6:$P$2005,1)+IF($C20=$B20,0,COUNTIFS('LANÇAMENTOS'!$I$6:$I$2005,$C20,'LANÇAMENTOS'!$P$6:$P$2005,1))) | R20: =IFERROR(IF($P20=0,"",$P20/$Q20),"") | S20: =IF($B20="","",IFERROR(IF(SUMPRODUCT(MAX(('LANÇAMENTOS'!$I$6:$I$2005=$B20)*'LANÇAMENTOS'!$B$6:$B$2005))>0,SUMPRODUCT(MAX(('LANÇAMENTOS'!$I$6:$I$2005=$B20)*'LANÇAMENTOS'!$B$6:$B$2005)),""),"")) | T20: =IF($B20="","",SUMIFS('LANÇAMENTOS'!$W$6:$W$2005,'LANÇAMENTOS'!$I$6:$I$2005,$B20,'LANÇAMENTOS'!$E$6:$E$2005,"Entrada")+IF($C20=$B20,0,SUMIFS('LANÇAMENTOS'!$W$6:$W$2005,'LANÇAMENTOS'!$I$6:$I$2005,$C20,'LANÇAMENTOS'!$E$6:$E$2005,"Entrada"))) | U20: =IF($B20="","",SUMIFS('LANÇAMENTOS'!$W$6:$W$2005,'LANÇAMENTOS'!$I$6:$I$2005,$B20,'LANÇAMENTOS'!$E$6:$E$2005,"Entrada",'LANÇAMENTOS'!$C$6:$C$2005,"<"&TODAY())+IF($C20=$B20,0,SUMIFS('LANÇAMENTOS'!$W$6:$W$2005,'LANÇAMENTOS'!$I$6:$I$2005,$C20,'LANÇAMENTOS'!$E$6:$E$2005,"Entrada",'LANÇAMENTOS'!$C$6:$C$2005,"<"&TODAY()))) | V20: =IF(OR($B20="",$U20=0),0,MAX(0,TODAY()-IFERROR(-SUMPRODUCT(MAX(('LANÇAMENTOS'!$I$6:$I$2005=$B20)*('LANÇAMENTOS'!$W$6:$W$2005>0)*('LANÇAMENTOS'!$C$6:$C$2005<TODAY())*(-'LANÇAMENTOS'!$C$6:$C$2005))),TODAY()))) | W20: =IF($B20="","",IF($N20="Bloqueado","⛔ Bloqueado",IF($U20>0,"⚠ Com valores vencidos","✔ Em dia")))
P21: =IF($B21="","",SUMIFS('LANÇAMENTOS'!$Q$6:$Q$2005,'LANÇAMENTOS'!$I$6:$I$2005,$B21)+IF($C21=$B21,0,SUMIFS('LANÇAMENTOS'!$Q$6:$Q$2005,'LANÇAMENTOS'!$I$6:$I$2005,$C21))) | Q21: =IF($B21="","",COUNTIFS('LANÇAMENTOS'!$I$6:$I$2005,$B21,'LANÇAMENTOS'!$P$6:$P$2005,1)+IF($C21=$B21,0,COUNTIFS('LANÇAMENTOS'!$I$6:$I$2005,$C21,'LANÇAMENTOS'!$P$6:$P$2005,1))) | R21: =IFERROR(IF($P21=0,"",$P21/$Q21),"") | S21: =IF($B21="","",IFERROR(IF(SUMPRODUCT(MAX(('LANÇAMENTOS'!$I$6:$I$2005=$B21)*'LANÇAMENTOS'!$B$6:$B$2005))>0,SUMPRODUCT(MAX(('LANÇAMENTOS'!$I$6:$I$2005=$B21)*'LANÇAMENTOS'!$B$6:$B$2005)),""),"")) | T21: =IF($B21="","",SUMIFS('LANÇAMENTOS'!$W$6:$W$2005,'LANÇAMENTOS'!$I$6:$I$2005,$B21,'LANÇAMENTOS'!$E$6:$E$2005,"Entrada")+IF($C21=$B21,0,SUMIFS('LANÇAMENTOS'!$W$6:$W$2005,'LANÇAMENTOS'!$I$6:$I$2005,$C21,'LANÇAMENTOS'!$E$6:$E$2005,"Entrada"))) | U21: =IF($B21="","",SUMIFS('LANÇAMENTOS'!$W$6:$W$2005,'LANÇAMENTOS'!$I$6:$I$2005,$B21,'LANÇAMENTOS'!$E$6:$E$2005,"Entrada",'LANÇAMENTOS'!$C$6:$C$2005,"<"&TODAY())+IF($C21=$B21,0,SUMIFS('LANÇAMENTOS'!$W$6:$W$2005,'LANÇAMENTOS'!$I$6:$I$2005,$C21,'LANÇAMENTOS'!$E$6:$E$2005,"Entrada",'LANÇAMENTOS'!$C$6:$C$2005,"<"&TODAY()))) | V21: =IF(OR($B21="",$U21=0),0,MAX(0,TODAY()-IFERROR(-SUMPRODUCT(MAX(('LANÇAMENTOS'!$I$6:$I$2005=$B21)*('LANÇAMENTOS'!$W$6:$W$2005>0)*('LANÇAMENTOS'!$C$6:$C$2005<TODAY())*(-'LANÇAMENTOS'!$C$6:$C$2005))),TODAY()))) | W21: =IF($B21="","",IF($N21="Bloqueado","⛔ Bloqueado",IF($U21>0,"⚠ Com valores vencidos","✔ Em dia")))
P22: =IF($B22="","",SUMIFS('LANÇAMENTOS'!$Q$6:$Q$2005,'LANÇAMENTOS'!$I$6:$I$2005,$B22)+IF($C22=$B22,0,SUMIFS('LANÇAMENTOS'!$Q$6:$Q$2005,'LANÇAMENTOS'!$I$6:$I$2005,$C22))) | Q22: =IF($B22="","",COUNTIFS('LANÇAMENTOS'!$I$6:$I$2005,$B22,'LANÇAMENTOS'!$P$6:$P$2005,1)+IF($C22=$B22,0,COUNTIFS('LANÇAMENTOS'!$I$6:$I$2005,$C22,'LANÇAMENTOS'!$P$6:$P$2005,1))) | R22: =IFERROR(IF($P22=0,"",$P22/$Q22),"") | S22: =IF($B22="","",IFERROR(IF(SUMPRODUCT(MAX(('LANÇAMENTOS'!$I$6:$I$2005=$B22)*'LANÇAMENTOS'!$B$6:$B$2005))>0,SUMPRODUCT(MAX(('LANÇAMENTOS'!$I$6:$I$2005=$B22)*'LANÇAMENTOS'!$B$6:$B$2005)),""),"")) | T22: =IF($B22="","",SUMIFS('LANÇAMENTOS'!$W$6:$W$2005,'LANÇAMENTOS'!$I$6:$I$2005,$B22,'LANÇAMENTOS'!$E$6:$E$2005,"Entrada")+IF($C22=$B22,0,SUMIFS('LANÇAMENTOS'!$W$6:$W$2005,'LANÇAMENTOS'!$I$6:$I$2005,$C22,'LANÇAMENTOS'!$E$6:$E$2005,"Entrada"))) | U22: =IF($B22="","",SUMIFS('LANÇAMENTOS'!$W$6:$W$2005,'LANÇAMENTOS'!$I$6:$I$2005,$B22,'LANÇAMENTOS'!$E$6:$E$2005,"Entrada",'LANÇAMENTOS'!$C$6:$C$2005,"<"&TODAY())+IF($C22=$B22,0,SUMIFS('LANÇAMENTOS'!$W$6:$W$2005,'LANÇAMENTOS'!$I$6:$I$2005,$C22,'LANÇAMENTOS'!$E$6:$E$2005,"Entrada",'LANÇAMENTOS'!$C$6:$C$2005,"<"&TODAY()))) | V22: =IF(OR($B22="",$U22=0),0,MAX(0,TODAY()-IFERROR(-SUMPRODUCT(MAX(('LANÇAMENTOS'!$I$6:$I$2005=$B22)*('LANÇAMENTOS'!$W$6:$W$2005>0)*('LANÇAMENTOS'!$C$6:$C$2005<TODAY())*(-'LANÇAMENTOS'!$C$6:$C$2005))),TODAY()))) | W22: =IF($B22="","",IF($N22="Bloqueado","⛔ Bloqueado",IF($U22>0,"⚠ Com valores vencidos","✔ Em dia")))
... P65: =IF($B65="","",SUMIFS('LANÇAMENTOS'!$Q$6:$Q$2005,'LANÇAMENTOS'!$I$6:$I$2005,$B65)+IF($C65=$B65,0,SUMIFS('LANÇAMENTOS'!$Q$6:$Q$2005,'LANÇAMENTOS'!$I$6:$I$2005,$C65))) | Q65: =IF($B65="","",COUNTIFS('LANÇAMENTOS'!$I$6:$I$2005,$B65,'LANÇAMENTOS'!$P$6:$P$2005,1)+IF($C65=$B65,0,COUNTIFS('LANÇAMENTOS'!$I$6:$I$2005,$C65,'LANÇAMENTOS'!$P$6:$P$2005,1))) | R65: =IFERROR(IF($P65=0,"",$P65/$Q65),"") | S65: =IF($B65="","",IFERROR(IF(SUMPRODUCT(MAX(('LANÇAMENTOS'!$I$6:$I$2005=$B65)*'LANÇAMENTOS'!$B$6:$B$2005))>0,SUMPRODUCT(MAX(('LANÇAMENTOS'!$I$6:$I$2005=$B65)*'LANÇAMENTOS'!$B$6:$B$2005)),""),"")) | T65: =IF($B65="","",SUMIFS('LANÇAMENTOS'!$W$6:$W$2005,'LANÇAMENTOS'!$I$6:$I$2005,$B65,'LANÇAMENTOS'!$E$6:$E$2005,"Entrada")+IF($C65=$B65,0,SUMIFS('LANÇAMENTOS'!$W$6:$W$2005,'LANÇAMENTOS'!$I$6:$I$2005,$C65,'LANÇAMENTOS'!$E$6:$E$2005,"Entrada"))) | U65: =IF($B65="","",SUMIFS('LANÇAMENTOS'!$W$6:$W$2005,'LANÇAMENTOS'!$I$6:$I$2005,$B65,'LANÇAMENTOS'!$E$6:$E$2005,"Entrada",'LANÇAMENTOS'!$C$6:$C$2005,"<"&TODAY())+IF($C65=$B65,0,SUMIFS('LANÇAMENTOS'!$W$6:$W$2005,'LANÇAMENTOS'!$I$6:$I$2005,$C65,'LANÇAMENTOS'!$E$6:$E$2005,"Entrada",'LANÇAMENTOS'!$C$6:$C$2005,"<"&TODAY()))) | V65: =IF(OR($B65="",$U65=0),0,MAX(0,TODAY()-IFERROR(-SUMPRODUCT(MAX(('LANÇAMENTOS'!$I$6:$I$2005=$B65)*('LANÇAMENTOS'!$W$6:$W$2005>0)*('LANÇAMENTOS'!$C$6:$C$2005<TODAY())*(-'LANÇAMENTOS'!$C$6:$C$2005))),TODAY()))) | W65: =IF($B65="","",IF($N65="Bloqueado","⛔ Bloqueado",IF($U65>0,"⚠ Com valores vencidos","✔ Em dia")))

Sheet CADASTRO DE FORNECEDORES
A1: CADASTRO DE FORNECEDORES
A2: Preencha as colunas amarelas. As colunas cinzas (P a T) são calculadas automaticamente a partir da aba LANÇAMENTOS.
B3: ⚠ DADOS DE EXEMPLO — fornecedores fictícios. Substitua pelos fornecedores reais.
A5: Código | B5: Razão social | C5: Nome fantasia | D5: CNPJ/CPF | E5: Contato | F5: Telefone | G5: E-mail | H5: Cidade | I5: UF | J5: Categoria principal | K5: Condição de pagamento | L5: Prazo médio (dias) | M5: Limite de crédito | N5: Status | O5: Observações | P5: Total comprado | Q5: Total pago | R5: Total em aberto | S5: Valor vencido | T5: Última compra
A6: FOR001 | B6: DISTRIBUIDORA CENTRAL DE ALIMENTOS S/A | C6: Central Foods | D6: 61.890.123/0001-66 | E6: Roberto Lima | F6: (11) 3701-2200 | G6: vendas@centralfoods.com.br | H6: São Paulo | I6: SP | J6: Mercadorias para Revenda | K6: Boleto 30 dias | L6: 30 | M6: 250000 | N6: Ativo | O6: Principal fornecedor de mercadorias | P6: =IF($B6="","",SUMIFS('LANÇAMENTOS'!$Q$6:$Q$2005,'LANÇAMENTOS'!$I$6:$I$2005,$B6,'LANÇAMENTOS'!$E$6:$E$2005,"Saída")) | Q6: =IF($B6="","",SUMIFS('LANÇAMENTOS'!$V$6:$V$2005,'LANÇAMENTOS'!$I$6:$I$2005,$B6,'LANÇAMENTOS'!$E$6:$E$2005,"Saída")) | R6: =IF($B6="","",SUMIFS('LANÇAMENTOS'!$W$6:$W$2005,'LANÇAMENTOS'!$I$6:$I$2005,$B6,'LANÇAMENTOS'!$E$6:$E$2005,"Saída")) | S6: =IF($B6="","",SUMIFS('LANÇAMENTOS'!$W$6:$W$2005,'LANÇAMENTOS'!$I$6:$I$2005,$B6,'LANÇAMENTOS'!$E$6:$E$2005,"Saída",'LANÇAMENTOS'!$C$6:$C$2005,"<"&TODAY())) | T6: =IF($B6="","",IFERROR(IF(SUMPRODUCT(MAX(('LANÇAMENTOS'!$I$6:$I$2005=$B6)*'LANÇAMENTOS'!$B$6:$B$2005))>0,SUMPRODUCT(MAX(('LANÇAMENTOS'!$I$6:$I$2005=$B6)*'LANÇAMENTOS'!$B$6:$B$2005)),""),""))
A7: FOR002 | B7: EMBALAGENS PAULISTA LTDA | C7: Embalagens Paulista | D7: 72.901.234/0001-77 | E7: Fernanda Dias | F7: (11) 2933-4455 | G7: comercial@embalagenspaulista.com.br | H7: São Bernardo do Campo | I7: SP | J7: Embalagens | K7: Boleto 15 dias | L7: 15 | M7: 40000 | N7: Ativo | P7: =IF($B7="","",SUMIFS('LANÇAMENTOS'!$Q$6:$Q$2005,'LANÇAMENTOS'!$I$6:$I$2005,$B7,'LANÇAMENTOS'!$E$6:$E$2005,"Saída")) | Q7: =IF($B7="","",SUMIFS('LANÇAMENTOS'!$V$6:$V$2005,'LANÇAMENTOS'!$I$6:$I$2005,$B7,'LANÇAMENTOS'!$E$6:$E$2005,"Saída")) | R7: =IF($B7="","",SUMIFS('LANÇAMENTOS'!$W$6:$W$2005,'LANÇAMENTOS'!$I$6:$I$2005,$B7,'LANÇAMENTOS'!$E$6:$E$2005,"Saída")) | S7: =IF($B7="","",SUMIFS('LANÇAMENTOS'!$W$6:$W$2005,'LANÇAMENTOS'!$I$6:$I$2005,$B7,'LANÇAMENTOS'!$E$6:$E$2005,"Saída",'LANÇAMENTOS'!$C$6:$C$2005,"<"&TODAY())) | T7: =IF($B7="","",IFERROR(IF(SUMPRODUCT(MAX(('LANÇAMENTOS'!$I$6:$I$2005=$B7)*'LANÇAMENTOS'!$B$6:$B$2005))>0,SUMPRODUCT(MAX(('LANÇAMENTOS'!$I$6:$I$2005=$B7)*'LANÇAMENTOS'!$B$6:$B$2005)),""),""))
A8: FOR003 | B8: TRANSPORTADORA RÁPIDA LOG LTDA | C8: Rápida Log | D8: 83.012.345/0001-88 | E8: José Almeida | F8: (11) 3011-9090 | G8: faturamento@rapidalog.com.br | H8: Guarulhos | I8: SP | J8: Fretes e Entregas sobre Vendas | K8: Boleto 15 dias | L8: 15 | M8: 60000 | N8: Ativo | O8: Frete faturado por nota fiscal | P8: =IF($B8="","",SUMIFS('LANÇAMENTOS'!$Q$6:$Q$2005,'LANÇAMENTOS'!$I$6:$I$2005,$B8,'LANÇAMENTOS'!$E$6:$E$2005,"Saída")) | Q8: =IF($B8="","",SUMIFS('LANÇAMENTOS'!$V$6:$V$2005,'LANÇAMENTOS'!$I$6:$I$2005,$B8,'LANÇAMENTOS'!$E$6:$E$2005,"Saída")) | R8: =IF($B8="","",SUMIFS('LANÇAMENTOS'!$W$6:$W$2005,'LANÇAMENTOS'!$I$6:$I$2005,$B8,'LANÇAMENTOS'!$E$6:$E$2005,"Saída")) | S8: =IF($B8="","",SUMIFS('LANÇAMENTOS'!$W$6:$W$2005,'LANÇAMENTOS'!$I$6:$I$2005,$B8,'LANÇAMENTOS'!$E$6:$E$2005,"Saída",'LANÇAMENTOS'!$C$6:$C$2005,"<"&TODAY())) | T8: =IF($B8="","",IFERROR(IF(SUMPRODUCT(MAX(('LANÇAMENTOS'!$I$6:$I$2005=$B8)*'LANÇAMENTOS'!$B$6:$B$2005))>0,SUMPRODUCT(MAX(('LANÇAMENTOS'!$I$6:$I$2005=$B8)*'LANÇAMENTOS'!$B$6:$B$2005)),""),""))
A9: FOR004 | B9: TECNOLOGIA E SISTEMAS ABC LTDA | C9: ABC Sistemas | D9: 94.123.456/0001-99 | E9: Marcelo Prado | F9: (11) 4063-1122 | G9: suporte@abcsistemas.com.br | H9: São Paulo | I9: SP | J9: Sistemas e Softwares | K9: Cartão de crédito | L9: 0 | M9: 15000 | N9: Ativo | O9: ERP, emissão de NF-e e BI | P9: =IF($B9="","",SUMIFS('LANÇAMENTOS'!$Q$6:$Q$2005,'LANÇAMENTOS'!$I$6:$I$2005,$B9,'LANÇAMENTOS'!$E$6:$E$2005,"Saída")) | Q9: =IF($B9="","",SUMIFS('LANÇAMENTOS'!$V$6:$V$2005,'LANÇAMENTOS'!$I$6:$I$2005,$B9,'LANÇAMENTOS'!$E$6:$E$2005,"Saída")) | R9: =IF($B9="","",SUMIFS('LANÇAMENTOS'!$W$6:$W$2005,'LANÇAMENTOS'!$I$6:$I$2005,$B9,'LANÇAMENTOS'!$E$6:$E$2005,"Saída")) | S9: =IF($B9="","",SUMIFS('LANÇAMENTOS'!$W$6:$W$2005,'LANÇAMENTOS'!$I$6:$I$2005,$B9,'LANÇAMENTOS'!$E$6:$E$2005,"Saída",'LANÇAMENTOS'!$C$6:$C$2005,"<"&TODAY())) | T9: =IF($B9="","",IFERROR(IF(SUMPRODUCT(MAX(('LANÇAMENTOS'!$I$6:$I$2005=$B9)*'LANÇAMENTOS'!$B$6:$B$2005))>0,SUMPRODUCT(MAX(('LANÇAMENTOS'!$I$6:$I$2005=$B9)*'LANÇAMENTOS'!$B$6:$B$2005)),""),""))
A10: FOR005 | B10: IMÓVEIS E LOCAÇÕES PINHEIROS LTDA | C10: Locadora Pinheiros | D10: 15.234.567/0001-10 | E10: Cláudia Rossi | F10: (11) 3812-7777 | G10: locacao@pinheirosimoveis.com.br | H10: São Paulo | I10: SP | J10: Aluguel | K10: Boleto 5 dias | L10: 5 | M10: 0 | N10: Ativo | O10: Contrato de locação do galpão — reajuste anual em janeiro | P10: =IF($B10="","",SUMIFS('LANÇAMENTOS'!$Q$6:$Q$2005,'LANÇAMENTOS'!$I$6:$I$2005,$B10,'LANÇAMENTOS'!$E$6:$E$2005,"Saída")) | Q10: =IF($B10="","",SUMIFS('LANÇAMENTOS'!$V$6:$V$2005,'LANÇAMENTOS'!$I$6:$I$2005,$B10,'LANÇAMENTOS'!$E$6:$E$2005,"Saída")) | R10: =IF($B10="","",SUMIFS('LANÇAMENTOS'!$W$6:$W$2005,'LANÇAMENTOS'!$I$6:$I$2005,$B10,'LANÇAMENTOS'!$E$6:$E$2005,"Saída")) | S10: =IF($B10="","",SUMIFS('LANÇAMENTOS'!$W$6:$W$2005,'LANÇAMENTOS'!$I$6:$I$2005,$B10,'LANÇAMENTOS'!$E$6:$E$2005,"Saída",'LANÇAMENTOS'!$C$6:$C$2005,"<"&TODAY())) | T10: =IF($B10="","",IFERROR(IF(SUMPRODUCT(MAX(('LANÇAMENTOS'!$I$6:$I$2005=$B10)*'LANÇAMENTOS'!$B$6:$B$2005))>0,SUMPRODUCT(MAX(('LANÇAMENTOS'!$I$6:$I$2005=$B10)*'LANÇAMENTOS'!$B$6:$B$2005)),""),""))
A11: FOR006 | B11: ENEL DISTRIBUIÇÃO SÃO PAULO | C11: Enel SP | D11: 61.695.227/0001-93 | E11: Central de Atendimento | F11: 0800 727 2116 | G11: atendimento@enel.com | H11: São Paulo | I11: SP | J11: Energia Elétrica | K11: Débito automático | L11: 10 | M11: 0 | N11: Ativo | O11: Concessionária de energia elétrica | P11: =IF($B11="","",SUMIFS('LANÇAMENTOS'!$Q$6:$Q$2005,'LANÇAMENTOS'!$I$6:$I$2005,$B11,'LANÇAMENTOS'!$E$6:$E$2005,"Saída")) | Q11: =IF($B11="","",SUMIFS('LANÇAMENTOS'!$V$6:$V$2005,'LANÇAMENTOS'!$I$6:$I$2005,$B11,'LANÇAMENTOS'!$E$6:$E$2005,"Saída")) | R11: =IF($B11="","",SUMIFS('LANÇAMENTOS'!$W$6:$W$2005,'LANÇAMENTOS'!$I$6:$I$2005,$B11,'LANÇAMENTOS'!$E$6:$E$2005,"Saída")) | S11: =IF($B11="","",SUMIFS('LANÇAMENTOS'!$W$6:$W$2005,'LANÇAMENTOS'!$I$6:$I$2005,$B11,'LANÇAMENTOS'!$E$6:$E$2005,"Saída",'LANÇAMENTOS'!$C$6:$C$2005,"<"&TODAY())) | T11: =IF($B11="","",IFERROR(IF(SUMPRODUCT(MAX(('LANÇAMENTOS'!$I$6:$I$2005=$B11)*'LANÇAMENTOS'!$B$6:$B$2005))>0,SUMPRODUCT(MAX(('LANÇAMENTOS'!$I$6:$I$2005=$B11)*'LANÇAMENTOS'!$B$6:$B$2005)),""),""))
A12: FOR007 | B12: SABESP — SANEAMENTO BÁSICO DO ESTADO DE SÃO PAULO | C12: Sabesp | D12: 43.776.517/0001-80 | E12: Central de Atendimento | F12: 0800 055 0195 | G12: atendimento@sabesp.com.br | H12: São Paulo | I12: SP | J12: Água e Saneamento | K12: Débito automático | L12: 12 | M12: 0 | N12: Ativo | O12: Concessionária de água | P12: =IF($B12="","",SUMIFS('LANÇAMENTOS'!$Q$6:$Q$2005,'LANÇAMENTOS'!$I$6:$I$2005,$B12,'LANÇAMENTOS'!$E$6:$E$2005,"Saída")) | Q12: =IF($B12="","",SUMIFS('LANÇAMENTOS'!$V$6:$V$2005,'LANÇAMENTOS'!$I$6:$I$2005,$B12,'LANÇAMENTOS'!$E$6:$E$2005,"Saída")) | R12: =IF($B12="","",SUMIFS('LANÇAMENTOS'!$W$6:$W$2005,'LANÇAMENTOS'!$I$6:$I$2005,$B12,'LANÇAMENTOS'!$E$6:$E$2005,"Saída")) | S12: =IF($B12="","",SUMIFS('LANÇAMENTOS'!$W$6:$W$2005,'LANÇAMENTOS'!$I$6:$I$2005,$B12,'LANÇAMENTOS'!$E$6:$E$2005,"Saída",'LANÇAMENTOS'!$C$6:$C$2005,"<"&TODAY())) | T12: =IF($B12="","",IFERROR(IF(SUMPRODUCT(MAX(('LANÇAMENTOS'!$I$6:$I$2005=$B12)*'LANÇAMENTOS'!$B$6:$B$2005))>0,SUMPRODUCT(MAX(('LANÇAMENTOS'!$I$6:$I$2005=$B12)*'LANÇAMENTOS'!$B$6:$B$2005)),""),""))
A13: FOR008 | B13: TELEFÔNICA BRASIL S.A. (VIVO EMPRESAS) | C13: Vivo Empresas | D13: 02.558.157/0001-62 | E13: Gestor de Contas | F13: 1058 | G13: empresas@vivo.com.br | H13: São Paulo | I13: SP | J13: Internet e Telefonia | K13: Cartão de crédito | L13: 0 | M13: 0 | N13: Ativo | O13: Link dedicado e telefonia móvel | P13: =IF($B13="","",SUMIFS('LANÇAMENTOS'!$Q$6:$Q$2005,'LANÇAMENTOS'!$I$6:$I$2005,$B13,'LANÇAMENTOS'!$E$6:$E$2005,"Saída")) | Q13: =IF($B13="","",SUMIFS('LANÇAMENTOS'!$V$6:$V$2005,'LANÇAMENTOS'!$I$6:$I$2005,$B13,'LANÇAMENTOS'!$E$6:$E$2005,"Saída")) | R13: =IF($B13="","",SUMIFS('LANÇAMENTOS'!$W$6:$W$2005,'LANÇAMENTOS'!$I$6:$I$2005,$B13,'LANÇAMENTOS'!$E$6:$E$2005,"Saída")) | S13: =IF($B13="","",SUMIFS('LANÇAMENTOS'!$W$6:$W$2005,'LANÇAMENTOS'!$I$6:$I$2005,$B13,'LANÇAMENTOS'!$E$6:$E$2005,"Saída",'LANÇAMENTOS'!$C$6:$C$2005,"<"&TODAY())) | T13: =IF($B13="","",IFERROR(IF(SUMPRODUCT(MAX(('LANÇAMENTOS'!$I$6:$I$2005=$B13)*'LANÇAMENTOS'!$B$6:$B$2005))>0,SUMPRODUCT(MAX(('LANÇAMENTOS'!$I$6:$I$2005=$B13)*'LANÇAMENTOS'!$B$6:$B$2005)),""),""))
A14: FOR009 | B14: CONTABILIDADE AURORA ASSESSORIA CONTÁBIL LTDA | C14: Contabilidade Aurora | D14: 18.447.902/0001-34 | E14: Sérgio Tavares | F14: (11) 3151-8080 | G14: contato@contabilaurora.com.br | H14: São Paulo | I14: SP | J14: Contabilidade | K14: PIX mensal | L14: 0 | M14: 0 | N14: Ativo | O14: Assessoria contábil e fiscal | P14: =IF($B14="","",SUMIFS('LANÇAMENTOS'!$Q$6:$Q$2005,'LANÇAMENTOS'!$I$6:$I$2005,$B14,'LANÇAMENTOS'!$E$6:$E$2005,"Saída")) | Q14: =IF($B14="","",SUMIFS('LANÇAMENTOS'!$V$6:$V$2005,'LANÇAMENTOS'!$I$6:$I$2005,$B14,'LANÇAMENTOS'!$E$6:$E$2005,"Saída")) | R14: =IF($B14="","",SUMIFS('LANÇAMENTOS'!$W$6:$W$2005,'LANÇAMENTOS'!$I$6:$I$2005,$B14,'LANÇAMENTOS'!$E$6:$E$2005,"Saída")) | S14: =IF($B14="","",SUMIFS('LANÇAMENTOS'!$W$6:$W$2005,'LANÇAMENTOS'!$I$6:$I$2005,$B14,'LANÇAMENTOS'!$E$6:$E$2005,"Saída",'LANÇAMENTOS'!$C$6:$C$2005,"<"&TODAY())) | T14: =IF($B14="","",IFERROR(IF(SUMPRODUCT(MAX(('LANÇAMENTOS'!$I$6:$I$2005=$B14)*'LANÇAMENTOS'!$B$6:$B$2005))>0,SUMPRODUCT(MAX(('LANÇAMENTOS'!$I$6:$I$2005=$B14)*'LANÇAMENTOS'!$B$6:$B$2005)),""),""))
A15: FOR010 | B15: AGÊNCIA PULSO DIGITAL LTDA | C15: Pulso Digital | D15: 29.334.556/0001-71 | E15: Renata Campos | F15: (11) 99123-4567 | G15: contato@pulsodigital.com.br | H15: São Paulo | I15: SP | J15: Marketing Digital | K15: Cartão de crédito | L15: 0 | M15: 20000 | N15: Ativo | O15: Gestão de mídia paga | P15: =IF($B15="","",SUMIFS('LANÇAMENTOS'!$Q$6:$Q$2005,'LANÇAMENTOS'!$I$6:$I$2005,$B15,'LANÇAMENTOS'!$E$6:$E$2005,"Saída")) | Q15: =IF($B15="","",SUMIFS('LANÇAMENTOS'!$V$6:$V$2005,'LANÇAMENTOS'!$I$6:$I$2005,$B15,'LANÇAMENTOS'!$E$6:$E$2005,"Saída")) | R15: =IF($B15="","",SUMIFS('LANÇAMENTOS'!$W$6:$W$2005,'LANÇAMENTOS'!$I$6:$I$2005,$B15,'LANÇAMENTOS'!$E$6:$E$2005,"Saída")) | S15: =IF($B15="","",SUMIFS('LANÇAMENTOS'!$W$6:$W$2005,'LANÇAMENTOS'!$I$6:$I$2005,$B15,'LANÇAMENTOS'!$E$6:$E$2005,"Saída",'LANÇAMENTOS'!$C$6:$C$2005,"<"&TODAY())) | T15: =IF($B15="","",IFERROR(IF(SUMPRODUCT(MAX(('LANÇAMENTOS'!$I$6:$I$2005=$B15)*'LANÇAMENTOS'!$B$6:$B$2005))>0,SUMPRODUCT(MAX(('LANÇAMENTOS'!$I$6:$I$2005=$B15)*'LANÇAMENTOS'!$B$6:$B$2005)),""),""))
A16: FOR011 | B16: GOOGLE BRASIL INTERNET LTDA | C16: Google Ads | D16: 06.990.590/0001-23 | E16: Suporte | F16: — | G16: ads@google.com | H16: São Paulo | I16: SP | J16: Publicidade e Anúncios | K16: Cartão de crédito | L16: 0 | M16: 0 | N16: Ativo | O16: Anúncios e campanhas digitais | P16: =IF($B16="","",SUMIFS('LANÇAMENTOS'!$Q$6:$Q$2005,'LANÇAMENTOS'!$I$6:$I$2005,$B16,'LANÇAMENTOS'!$E$6:$E$2005,"Saída")) | Q16: =IF($B16="","",SUMIFS('LANÇAMENTOS'!$V$6:$V$2005,'LANÇAMENTOS'!$I$6:$I$2005,$B16,'LANÇAMENTOS'!$E$6:$E$2005,"Saída")) | R16: =IF($B16="","",SUMIFS('LANÇAMENTOS'!$W$6:$W$2005,'LANÇAMENTOS'!$I$6:$I$2005,$B16,'LANÇAMENTOS'!$E$6:$E$2005,"Saída")) | S16: =IF($B16="","",SUMIFS('LANÇAMENTOS'!$W$6:$W$2005,'LANÇAMENTOS'!$I$6:$I$2005,$B16,'LANÇAMENTOS'!$E$6:$E$2005,"Saída",'LANÇAMENTOS'!$C$6:$C$2005,"<"&TODAY())) | T16: =IF($B16="","",IFERROR(IF(SUMPRODUCT(MAX(('LANÇAMENTOS'!$I$6:$I$2005=$B16)*'LANÇAMENTOS'!$B$6:$B$2005))>0,SUMPRODUCT(MAX(('LANÇAMENTOS'!$I$6:$I$2005=$B16)*'LANÇAMENTOS'!$B$6:$B$2005)),""),""))
